Workbook

Sheet Cover
B3: AMERICAN DREAM APARTMENTS
B4: Financial Model — Phase 1 Pre-Launch
B5: Plot MN/I/1691 · Nyali, Mombasa · Sierra USA Homes Ltd.
B10: Model Date | C10: 2026-04-11
B11: Model Version | C11: v2.0 (88-unit model)
B12: Prepared By | C12: Claude Sonnet 4.6 (AI) / Sierra USA Homes Ltd.
B13: Status | C13: Working Draft — For Internal Review
B14: Total Units | C14: 88
B15: Towers | C15: 3 (Lincoln · Washington · Benjamin-Franklin)
B16: Location | C16: Nyali, Mombasa County, Kenya
B17: Target Completion | C17: August 2029
B18: Hard Costs (KES) | C18: 660,000,000
B19: Total Dev Cost (KES) | C19: 784,082,921
B20: Total Revenue (KES) | C20: 1,500,000,000
B21: Net Profit (KES) | C21: 715,917,079
B22: ROI | C22: 91.3%
B25: Sheet Index
B26: Assumptions | C26: All model inputs — prices, costs, allocations, timing
B27: Unit_Programme | C27: 88-unit allocation: landowner / off-plan / on-market
B28: Revenue | C28: Revenue model by unit type and sales channel
B29: Dev_Cost | C29: Hard costs + itemised soft costs + total dev cost
B30: PL_Summary | C30: P&L summary — revenue, cost, profit, ROI
B31: Cash_Flow | C31: Quarterly cash flow Q3-2026 to Q3-2029
B32: Investor_Returns | C32: Investor return scenarios
B33: Unit_Tracker | C33: Unit-by-unit sales tracker (all 88 units)

Sheet Assumptions
B2: ASSUMPTIONS
A4: A. UNIT PRICING (KES)
A5: Parameter | B5: Value | E5: Notes
B6: 1BR Off-Plan Price (KES) | C6: 10000000 | E6: Benjamin-Franklin Tower – Franklin Wing
B7: 1BR On-Market Price (KES) | C7: 13000000 | E7: 966.44 sqft / 89.8 sqm
B8: 2BR Off-Plan Price (KES) | C8: 17000000 | E8: Benjamin-Franklin Tower – Benjamin Wing
B9: 2BR On-Market Price (KES) | C9: 22000000 | E9: 1,311.18 sqft / 121.8 sqm
B10: 3BR Off-Plan Price (KES) | C10: 23000000 | E10: Lincoln & Washington Towers
B11: 3BR On-Market Price (KES) | C11: 30000000 | E11: 2,617.58 sqft / 243.2 sqm
A13: B. UNIT COUNTS
A14: Parameter | B14: Value | E14: Notes
B15: Total Units | C15: 88 | E15: 3 towers confirmed
B16: 1BR Units (total) | C16: 22 | E16: Franklin Wing — Benjamin-Franklin Tower
B17: 2BR Units (total) | C17: 22 | E17: Benjamin Wing — Benjamin-Franklin Tower
B18: 3BR Units (total) | C18: 44 | E18: Lincoln (22) + Washington (22)
A20: C. LAND DEAL — 22% EQUITY TO LANDOWNERS
A21: Parameter | B21: Value | E21: Notes
B22: Landowner % allocation | C22: 0.22 | E22: Equity deal — no cash land purchase
B23: Landowner units (full) | C23: 19 | E23: Floor(88 × 22%) = 19
B24: Fractional residual (units) | C24: 0.36 | E24: (88 × 22%) – 19 = 0.36
B25: Landowner 1BR units | C25: 5 | E25: Proportional mix (25%)
B26: Landowner 2BR units | C26: 5 | E26: Proportional mix (25%)
B27: Landowner 3BR units | C27: 9 | E27: Proportional mix (50%)
B28: Fractional cash (KES) | C28: 8280000 | E28: 0.36 × 3BR off-plan rate (KES 23M)
A30: D. DEVELOPER SALES PROGRAMME
A31: Parameter | B31: Value | E31: Notes
B32: Developer units total | C32: 69 | E32: 88 – 19 landowner = 69
B33: Off-plan 3BR units | C33: 20 | E33: Priority: 3BR first
B34: Off-plan 2BR units | C34: 1 | E34: Minimum off-plan 2BR
B35: Off-plan 1BR units | C35: 0 | E35: 1BR sold on-market only
B36: On-market 3BR units | C36: 15 | E36: 35 total dev 3BR – 20 off-plan
B37: On-market 2BR units | C37: 16 | E37: 17 total dev 2BR – 1 off-plan
B38: On-market 1BR units | C38: 17 | E38: All 17 dev 1BR on-market
A40: E. CONSTRUCTION COSTS (HARD)
A41: Parameter | B41: Value | E41: Notes
B42: 1BR construction cost/unit (KES) | C42: 4000000 | E42: Source: ROI Breakdown xlsx, 2026-03
B43: 2BR construction cost/unit (KES) | C43: 6000000 | E43: Source: ROI Breakdown xlsx, 2026-03
B44: 3BR construction cost/unit (KES) | C44: 10000000 | E44: Source: ROI Breakdown xlsx, 2026-03
A46: F. SOFT COSTS (FIXED)
A47: Cost Item | B47: KES | E47: Notes
...

Sheet Unit_Programme
B2: UNIT PROGRAMME — 88 UNITS
A4: UNIT ALLOCATION SUMMARY
A5: Category | B5: 1BR | C5: 2BR | D5: 3BR | E5: Total Units | F5: Total Value (KES) | G5: Notes
B6: Landowner Units (22%) | C6: 5 | D6: 5 | E6: 9 | F6: =C6+D6+E6 -> 19 | G6: Equity deal — no cash
B7: Off-Plan Sales (Developer) | C7: 0 | D7: 1 | E7: 20 | F7: =C7+D7+E7 -> 21 | G7: ~60% op. budget coverage
B8: On-Market Sales (Developer) | C8: 17 | D8: 16 | E8: 15 | F8: =C8+D8+E8 -> 48 | G8: Balance at completion
B9: Fractional Residual (Cash — 0.36 units) | E9: (0.36) | F9: 8280000 | G9: 0.36 × KES 23M off-plan rate
B10: TOTAL | C10: =SUM(C6:C8) -> 22 | D10: =SUM(D6:D8) -> 22 | E10: =SUM(E6:E8) -> 44 | F10: =SUM(F6:F8)+F9 -> 8280088
A12: DEVELOPER UNITS DETAIL
A13: Channel | B13: 1BR | C13: 2BR | D13: 3BR | E13: Total | F13: Revenue (KES) | G13: Price Basis
B14: Off-Plan | C14: 0 | D14: 1 | E14: 20 | F14: =C14+D14+E14 -> 21 | G14: =C14*10000000+D14*17000000+E14*23000000 -> 477000000
B15: On-Market | C15: 17 | D15: 16 | E15: 15 | F15: =C15+D15+E15 -> 48 | G15: =C15*13000000+D15*22000000+E15*30000000 -> 1023000000
B16: Developer Total | C16: =SUM(C14:C15) -> 17 | D16: =SUM(D14:D15) -> 17 | E16: =SUM(E14:E15) -> 35 | F16: =SUM(F14:F15) -> 69 | G16: =SUM(G14:G15) -> 1500000000
A18: TOWER BREAKDOWN
A19: Tower | B19: Unit Type | C19: Total Units | D19: Size (sqft) | E19: Size (sqm) | F19: Floor Config
B20: Lincoln Tower | C20: 3 Bedroom | D20: 22 | E20: 2,617.58 | F20: 243.2 | G20: 11 floors × 2 units/floor
B21: Washington Tower | C21: 3 Bedroom | D21: 22 | E21: 2,617.58 | F21: 243.2 | G21: 11 floors × 2 units/floor
B22: BF Tower — Benjamin Wing | C22: 2 Bedroom | D22: 22 | E22: 1,311.18 | F22: 121.8 | G22: 11 floors × 2 units/floor
B23: BF Tower — Franklin Wing | C23: 1 Bedroom | D23: 22 | E23: 966.44 | F23: 89.8 | G23: 11 floors × 2 units/floor

Sheet Revenue
B2: REVENUE MODEL
A4: OFF-PLAN REVENUE (Developer Units)
A5: Unit Type | B5: Units | C5: Price/Unit (KES) | D5: Revenue (KES)
B6: 3 Bedroom | C6: 20 | D6: 23000000 | E6: =C6*D6 -> 460000000
B7: 2 Bedroom | C7: 1 | D7: 17000000 | E7: =C7*D7 -> 17000000
B8: 1 Bedroom | C8: 0 | D8: 10000000 | E8: =C8*D8 -> 0
B9: Off-Plan Sub-Total | C9: =SUM(C6:C8) -> 21 | E9: =SUM(E6:E8) -> 477000000
A11: ON-MARKET REVENUE (Developer Units)
A12: Unit Type | B12: Units | C12: Price/Unit (KES) | D12: Revenue (KES)
B13: 3 Bedroom | C13: 15 | D13: 30000000 | E13: =C13*D13 -> 450000000
B14: 2 Bedroom | C14: 16 | D14: 22000000 | E14: =C14*D14 -> 352000000
B15: 1 Bedroom | C15: 17 | D15: 13000000 | E15: =C15*D15 -> 221000000
B16: On-Market Sub-Total | C16: =SUM(C13:C15) -> 48 | E16: =SUM(E13:E15) -> 1023000000
B18: Fractional Residual Cash (Landowner) | E18: 8280000
B20: TOTAL GROSS REVENUE | E20: =E9+E16+E18 -> 1508280000
A22: REVENUE METRICS
B23: Off-Plan Revenue | E23: =E9 -> 477000000
B24: On-Market Revenue | E24: =E16 -> 1023000000
B25: Off-Plan as % of Total Revenue | E25: =E9/E20 -> 0.31625428
B26: Revenue per Developer Unit (avg) | E26: =(E9+E16)/69 -> 21739130
B27: Off-Plan Units as % of Developer Units | E27: =C9/69 -> 0.30434783

Sheet Dev_Cost
B2: DEVELOPMENT COST
A4: HARD COSTS (CONSTRUCTION)
A5: Unit Type | B5: Units | C5: Cost/Unit (KES) | D5: Total (KES) | E5: % of Hard Costs
B6: 1 Bedroom | C6: 22 | D6: 4000000 | E6: =C6*D6 -> 88000000
B7: 2 Bedroom | C7: 22 | D7: 6000000 | E7: =C7*D7 -> 132000000
B8: 3 Bedroom | C8: 44 | D8: 10000000 | E8: =C8*D8 -> 440000000
B9: Hard Costs Total | C9: =SUM(C6:C8) -> 88 | E9: =SUM(E6:E8) -> 660000000
A11: SOFT COSTS (FIXED)
A12: Cost Item | C12: Amount (KES) | D12: % of Total Dev Cost
B13: Project Management Costs | D13: 9341531
B14: Marketing Costs | D14: 24910750
B15: Permit Cost | D15: 10000000
B16: Lawyer Fees | D16: 300000
B17: Land Search | D17: 15000
B18: Architects, Engineers & Consultants | D18: 34514640
B19: Fixed Soft Costs Total | D19: =SUM(D13:D18) -> 79081921
A21: SOFT COSTS (VARIABLE)
A22: Cost Item | C22: Amount (KES) | D22: Basis
B23: Sales Commission (3% of Revenue) | D23: =Revenue!E20*0.03 -> 45248400 | E23: 3% × Total Revenue
B24: Variable Soft Costs Total | D24: =D23 -> 45248400
B26: TOTAL DEVELOPMENT COST | D26: =E9+D19+D24 -> 784330321
A28: COST METRICS
B29: Hard cost per unit (avg) | D29: =E9/88 -> 7500000
B30: Hard cost per sqft (blended) | D30: =E9/173208 -> 3810.4476
B31: Total dev cost per unit (avg) | D31: =D26/88 -> 8912844.6
B32: Hard cost as % of total dev cost | D32: =E9/D26 -> 0.84148219
B33: Soft cost as % of total dev cost | D33: =(D19+D24)/D26 -> 0.15851781

Sheet PL_Summary
B2: PROFIT & LOSS SUMMARY | C2: American Dream Apartments — 88 Units
A4: INCOME
B5: Off-Plan Sales Revenue | C5: =Revenue!E9 -> 477000000
B6: On-Market Sales Revenue | C6: =Revenue!E16 -> 1023000000
B7: Fractional Residual Cash | C7: =Revenue!E18 -> 8280000
B8: Gross Revenue | C8: =Revenue!E20 -> 1508280000
A10: COSTS
B11: Hard Construction Costs | C11: =Dev_Cost!E9 -> 660000000
B12: Fixed Soft Costs | C12: =Dev_Cost!D19 -> 79081921
B13: Sales Commission (Variable) | C13: =Dev_Cost!D24 -> 45248400
B14: Total Development Cost | C14: =Dev_Cost!D26 -> 784330321
B16: NET DEVELOPER PROFIT | C16: =C8-C14 -> 723949679
A18: RETURN METRICS
B19: Developer ROI (Net Profit / Dev Cost) | C19: =C16/C14 -> 0.92301631
B20: Gross Margin (Net Profit / Revenue) | C20: =C16/C8 -> 0.47998361
B21: Revenue / Development Cost (multiple) | C21: =C8/C14 -> 1.9230163
B22: Net Profit per Developer Unit (avg) | C22: =C16/69 -> 10492024
B23: Net Profit per Total Unit (avg) | C23: =C16/88 -> 8226700.9
B24: Off-Plan Revenue (KES) | C24: =Revenue!E9 -> 477000000
B25: Off-Plan % of Operating Budget | C25: =Revenue!E9/C14 -> 0.60816213

Sheet Cash_Flow
B2: QUARTERLY CASH FLOW
B4: LINE ITEM | C4: Q3-26 | D4: Q4-26 | E4: Q1-27 | F4: Q2-27 | G4: Q3-27 | H4: Q4-27 | I4: Q1-28 | J4: Q2-28 | K4: Q3-28 | L4: Q4-28 | M4: Q1-29 | N4: Q2-29 | O4: Q3-29 | P4: TOTAL
A5: INFLOWS
B6: Off-Plan Receipts (50% deposit) | C6: 238500000 | D6: 0 | E6: 0 | F6: 0 | G6: 0 | H6: 0 | I6: 0 | J6: 0 | K6: 0 | L6: 0 | M6: 0 | N6: 0 | O6: 0 | P6: =SUM(C6:O6) -> 238500000
B7: Off-Plan Receipts (50% balance) | C7: 0 | D7: 0 | E7: 0 | F7: 0 | G7: 0 | H7: 0 | I7: 0 | J7: 0 | K7: 0 | L7: 0 | M7: 0 | N7: 0 | O7: 238500000 | P7: =SUM(C7:O7) -> 238500000
B8: On-Market Receipts | C8: 20460000 | D8: 20460000 | E8: 20460000 | F8: 20460000 | G8: 20460000 | H8: 30690000 | I8: 51150000 | J8: 81840000 | K8: 102300000 | L8: 122760000 | M8: 153450000 | N8: 173910000 | O8: 204600000 | P8: =SUM(C8:O8) -> 1023000000
B9: Fractional Cash (Landowner) | C9: 8280000 | D9: 0 | E9: 0 | F9: 0 | G9: 0 | H9: 0 | I9: 0 | J9: 0 | K9: 0 | L9: 0 | M9: 0 | N9: 0 | O9: 0 | P9: =SUM(C9:O9) -> 8280000
B10: Total Inflows | C10: =SUM(C6:C9) -> 267240000 | D10: =SUM(D6:D9) -> 20460000 | E10: =SUM(E6:E9) -> 20460000 | F10: =SUM(F6:F9) -> 20460000 | G10: =SUM(G6:G9) -> 20460000 | H10: =SUM(H6:H9) -> 30690000 | I10: =SUM(I6:I9) -> 51150000 | J10: =SUM(J6:J9) -> 81840000 | ... O10: =SUM(O6:O9) -> 443100000 | P10: =SUM(C10:O10) -> 1508280000
A12: OUTFLOWS
B13: Hard Construction Costs | C13: 33000000 | D13: 66000000 | E13: 52800000 | F13: 52800000 | G13: 59400000 | H13: 59400000 | I13: 66000000 | J13: 66000000 | K13: 59400000 | L13: 52800000 | M13: 39600000 | N13: 26400000 | O13: 26400000 | P13: =SUM(C13:O13) -> 660000000
B14: Fixed Soft Costs | C14: 7908292 | D14: 7908292 | E14: 6326634 | F14: 6326634 | G14: 6326634 | H14: 6326634 | I14: 6326634 | J14: 6326634 | K14: 6326634 | L14: 4744975 | M14: 4744975 | N14: 4744975 | O14: 4744975 | P14: =SUM(C14:O14) -> 79082922
B15: Sales Commission (3%) | C15: 8017200 | D15: 613800 | E15: 613800 | F15: 613800 | G15: 613800 | H15: 920700 | I15: 1534500 | J15: 2455200 | K15: 3069000 | L15: 3682800 | M15: 4603500 | N15: 5217300 | O15: 13293000 | P15: =SUM(C15:O15) -> 45248400
B16: Total Outflows | C16: =SUM(C13:C15) -> 48925492 | D16: =SUM(D13:D15) -> 74522092 | E16: =SUM(E13:E15) -> 59740434 | F16: =SUM(F13:F15) -> 59740434 | G16: =SUM(G13:G15) -> 66340434 | H16: =SUM(H13:H15) -> 66647334 | I16: =SUM(I13:I15) -> 73861134 | J16: =SUM(J13:J15) -> 74781834 | ... O16: =SUM(O13:O15) -> 44437975 | P16: =SUM(C16:O16) -> 784331322
B17: NET CASH FLOW (QUARTERLY) | C17: =C10-C16 -> 218314508 | D17: =D10-D16 -> -54062092 | E17: =E10-E16 -> -39280434 | F17: =F10-F16 -> -39280434 | G17: =G10-G16 -> -45880434 | H17: =H10-H16 -> -35957334 | I17: =I10-I16 -> -22711134 | J17: =J10-J16 -> 7058166 | ... O17: =O10-O16 -> 398662025 | P17: =SUM(C17:O17) -> 723948678
B18: CUMULATIVE CASH FLOW | C18: =C17 -> 218314508 | D18: =C18+D17 -> 164252416 | E18: =D18+E17 -> 124971982 | F18: =E18+F17 -> 85691548 | G18: =F18+G17 -> 39811114 | H18: =G18+H17 -> 3853780 | I18: =H18+I17 -> -18857354 | J18: =I18+J17 -> -11799188 | K18: =J18+K17 -> 21705178 | ... O18: =N18+O17 -> 723948678

Sheet Investor_Returns
B2: INVESTOR RETURNS | C2: Scenario Analysis — Off-Plan Buyer
A4: OFF-PLAN BUYER RETURN (Resale at Completion)
A5: Unit Type | B5: Off-Plan Price (KES) | C5: On-Market Price (KES) | D5: Capital Gain (KES) | E5: ROI on Investment | F5: Appreciation %
B6: 1 Bedroom | C6: 10000000 | D6: 13000000 | E6: =D6-C6 -> 3000000 | F6: =E6/C6 -> 0.3
B7: 2 Bedroom | C7: 17000000 | D7: 22000000 | E7: =D7-C7 -> 5000000 | F7: =E7/C7 -> 0.29411765
B8: 3 Bedroom | C8: 23000000 | D8: 30000000 | E8: =D8-C8 -> 7000000 | F8: =E8/C8 -> 0.30434783
A11: PROJECT INVESTOR SUMMARY
B12: Total Project Revenue (KES) | C12: =PL_Summary!C8 -> 1508280000
B13: Total Development Cost (KES) | C13: =PL_Summary!C14 -> 784330321
B14: Net Developer Profit (KES) | C14: =PL_Summary!C16 -> 723949679
B15: Developer ROI | C15: =PL_Summary!C16/PL_Summary!C14 -> 0.92301631
B16: Gross Margin | C16: =PL_Summary!C16/PL_Summary!C8 -> 0.47998361
B17: Revenue Multiple (Rev/Dev Cost) | C17: =PL_Summary!C8/PL_Summary!C14 -> 1.9230163
B18: Project Duration | C18: ~36 months (Q3-2026 to Q3-2029)
B19: Off-Plan Discount to On-Market (3BR) | C19: =1-(23000000/30000000) -> 0.23333333
B20: Off-Plan Discount to On-Market (2BR) | C20: =1-(17000000/22000000) -> 0.22727273
B21: Off-Plan Discount to On-Market (1BR) | C21: =1-(10000000/13000000) -> 0.23076923

Sheet Unit_Tracker
B2: UNIT TRACKER — ALL 88 UNITS
A4: Unit ID | B4: Tower | C4: Type | D4: Floor | E4: Allocation | F4: Status | G4: List Price (KES) | H4: Buyer / Notes
B5: LC.1-01 | C5: Lincoln Tower | D5: 3BR | E5: 1 | F5: Landowner | G5: Landowner Reserved | H5: 23000000
B6: LC.1-02 | C6: Lincoln Tower | D6: 3BR | E6: 1 | F6: Landowner | G6: Landowner Reserved | H6: 23000000
B7: LC.2-03 | C7: Lincoln Tower | D7: 3BR | E7: 2 | F7: Landowner | G7: Landowner Reserved | H7: 23000000
B8: LC.2-04 | C8: Lincoln Tower | D8: 3BR | E8: 2 | F8: Landowner | G8: Landowner Reserved | H8: 23000000
B9: LC.3-05 | C9: Lincoln Tower | D9: 3BR | E9: 3 | F9: Landowner | G9: Landowner Reserved | H9: 23000000
B10: LC.3-06 | C10: Lincoln Tower | D10: 3BR | E10: 3 | F10: Landowner | G10: Landowner Reserved | H10: 23000000
B11: LC.4-07 | C11: Lincoln Tower | D11: 3BR | E11: 4 | F11: Landowner | G11: Landowner Reserved | H11: 23000000
B12: LC.4-08 | C12: Lincoln Tower | D12: 3BR | E12: 4 | F12: Landowner | G12: Landowner Reserved | H12: 23000000
B13: LC.5-09 | C13: Lincoln Tower | D13: 3BR | E13: 5 | F13: Landowner | G13: Landowner Reserved | H13: 23000000
B14: LC.5-10 | C14: Lincoln Tower | D14: 3BR | E14: 5 | F14: Off-Plan | G14: Available | H14: 23000000
B15: LC.6-11 | C15: Lincoln Tower | D15: 3BR | E15: 6 | F15: Off-Plan | G15: Available | H15: 23000000
B16: LC.6-12 | C16: Lincoln Tower | D16: 3BR | E16: 6 | F16: Off-Plan | G16: Available | H16: 23000000
... B92: FK.11-22 | C92: BF Tower — Franklin Wing | D92: 1BR | E92: 11 | F92: On-Market | G92: Available | H92: 13000000
A94: ALLOCATION SUMMARY
A95: Allocation | B95: 3BR | C95: 2BR | D95: 1BR | E95: Total
B96: Landowner | C96: 9 | D96: 5 | E96: 5 | F96: =C96+D96+E96 -> 19
B97: Off-Plan | C97: 20 | D97: 1 | E97: 0 | F97: =C97+D97+E97 -> 21
B98: On-Market | C98: 15 | D98: 16 | E98: 17 | F98: =C98+D98+E98 -> 48
B99: TOTAL | C99: =SUM(C96:C98) -> 44 | D99: =SUM(D96:D98) -> 22 | E99: =SUM(E96:E98) -> 22 | F99: =SUM(F96:F98) -> 88
