Workbook

Sheet LinkedIn Content Calendar
A1: AI Memory Brain — LinkedIn Content Calendar | April–May 2026
A2: Date | B2: Day | C2: Wk | D2: Week Theme | E2: Content Pillar | F2: ICP Segment | G2: Post Format | H2: Hook / Headline | I2: Key Message & Body Direction | J2: Supporting Asset Needed | K2: Source Material | L2: CTA | M2: Status | N2: Notes
A3: WEEK 1 — THE PROBLEM: Context Rot
A4: Apr 7, 2026 | B4: Mon | C4: 1 | D4: The Problem | E4: Context Rot | F4: All Segments | G4: Text Post | H4: Every AI session starts with total amnesia. Here's what that's actually costing you. | I4: Introduce the concept of Context Rot: every LLM session begins from zero. Re-explaining stack decisions, re-describing your ICP, re-briefing architecture — over and over. Quantify: 10–15 minutes per session × 20 sessions = 3–5 hours/month of pure waste. End with a teaser: 'There's an architecture that solves this.' | J4: None — pure text | K4: White Paper §1: Context Rot; Faruq conversation | L4: Like/share if you've experienced this | M4: Draft | N4: Kick-off post. Sets the problem frame for all future content.
A5: Apr 8, 2026 | B5: Tue | C5: 1 | D5: The Problem | E5: Context Rot | F5: Operations Leaders | G5: Data / Stats Post | H5: Your team spent 4 hours last week re-explaining context to AI. Here's the math. | I5: Build out the compounding cost argument from the white paper. Session 1: explain from scratch. Session 5: AI re-discovers a bug fixed in Session 2. Session 20: architectural drift because AI contradicts Session 3. Frame this as technical debt that doesn't show up in code review. Ops leaders feel this acutely across Sales, Marketing, Finance. | J5: Simple table graphic (Session # vs. Without/With AI Memory) | K5: White Paper §1.2: Compounding Cost | L5: Tag a RevOps leader who'd relate to this | M5: Draft | N5: Exhibit 1 table from white paper is perfect visual here.
A6: Apr 9, 2026 | B6: Wed | C6: 1 | D6: The Problem | E6: Context Rot | F6: AI Agent Builders | G6: Question / Discussion Post | H6: What happens to your AI agent's accumulated knowledge when the context window closes? | I6: Open-ended question targeted at builders. Acknowledge the common 'workarounds' (system prompts, RAG, chat history) and why each falls short. Reference the white paper comparison table. Position this as a universal problem every builder hits in production. Goal: drive comments from builders sharing their pain. | J6: None — pure text with question | K6: White Paper §2: Why Existing Approaches Fall Short | L6: Drop your current workaround in the comments | M6: Draft | N6: High engagement potential. Reply to every comment.
A7: Apr 10, 2026 | B7: Thu | C7: 1 | D7: The Problem | E7: Context Rot | F7: B2B Lead Gen Operators | G7: Storytelling Post | H7: I managed 77 user stories across 3 projects with AI. Here's what happened to the knowledge every time a session ended. | I7: Story format from Faruq's perspective (position as a case study). 77 stories, 22 sessions, and the AI kept starting from scratch until the memory system was built. Bridge to the B2B angle: imagine running 50 client campaigns and your AI forgets each client's ICP, brand voice, and winning angles every single session. That's the problem. | J7: None — storytelling post | K7: White Paper §7: 3 Live Deployments; Faruq conversation | L7: Save this post for when you're re-explaining context again | M7: Draft | N7: Narrative hook. Faruq's voice works well here.
A8: Apr 11, 2026 | B8: Fri | C8: 1 | D8: The Problem | E8: Context Rot | F8: All Segments | G8: Engagement / Poll | H8: What do you re-explain to AI every single session? | I8: Poll format: options like 'My tech stack / tools', 'Client or customer context', 'My brand voice and style', 'Project history and decisions'. Follow-up text: 'If you picked any of the above — there's a system that eliminates that.' Light teaser for Week 2. | J8: LinkedIn Poll (4 options) | K8: ICP Analysis: all segment pain points | L8: Vote + comment your most painful re-explanation | M8: Draft | N8: End-of-week engagement reset. Poll drives reach.
A9: WEEK 2 — THE ARCHITECTURE: The Solution
A10: Apr 14, 2026 | B10: Mon | C10: 2 | D10: The Architecture | E10: Architecture | F10: AI Agent Builders | G10: Carousel / Infographic | H10: 3-tier lazy loading: how AI Memory Brain loads only what it needs — using <5% of the context window. | I10: Visualize the 3-tier diagram from the white paper. Tier 1: Always Read (Master context, architecture, 2 recent sessions — <10K tokens). Tier 2: Index Only (scan keywords, drill on match — 50+ decision files in <1K tokens). Tier 3: On-Demand (production guides, API keys, archives — never loaded speculatively). Explain why this beats RAG and vector DBs. | J10: 3-tier diagram (Exhibit 1 from white paper) | K10: White Paper §3.1: Three-Tier Lazy-Loading Memory Model | L10: Save this diagram for your next agent architecture review | M10: Draft | N10: First architecture reveal post. Should generate saves.
A11: Apr 15, 2026 | B11: Tue | C11: 2 | D11: The Architecture | E11: Architecture | F11: Operations Leaders | G11: Framework Post | H11: The Session Lifecycle Protocol: the 3-phase system that makes AI memory work in production. | I11: Lay out the lifecycle: Open (git sync → load Tier 1 → scan Tier 2 → create live files → summarize). Active Work (live file pattern: write continuously, not at session end). Close (finalize files, update all indexes, recategorize risks, push to git). Emphasize for ops leaders: this is what 'AI discipline' looks like organizationally. | J11: Linear diagram: Open → Work → Close | K11: White Paper §4: Session Lifecycle Protocol | L11: Does your team have a session open/close discipline for AI? | M11: Draft | N11: Faruq's open/close mandate from conversation reinforces this.
A12: Apr 16, 2026 | B12: Wed | C12: 2 | D12: The Architecture | E12: Architecture | F12: Enterprise CTOs | G12: Technical Deep Dive | H12: 51 domain agents across 20 departments. One shared memory architecture. Here's how it works. | I12: For the CTO audience: explain the departmental folder structure (Exhibit 3 from white paper). Marketing, Security, Finance, Product Dev, Executive, Operations, TechSupport, etc. Each folder follows the same protocol. One MCP server shared across all projects. Keyword-indexed decision files. Full git audit trail. Model-agnostic. No vector DB. No embeddings. No retraining. | J12: Folder structure diagram (Exhibit 3 from white paper) | K12: White Paper §5: Departmental File Organization; ICP §7 | L12: Book a technical architecture briefing | M12: Draft | N12: Most technical post of the week. High-value for CTO segment.
A13: Apr 17, 2026 | B13: Thu | C13: 2 | D13: The Architecture | E13: Architecture | F13: B2B Lead Gen Operators | G13: Before / After Post | H13: 10–15 minutes to brief AI on a client campaign → 30 seconds. What changed. | I13: Before/After format targeting lead gen operators. Before: every session, re-explain client ICP, campaign history, brand voice, objection handling, winning angles. After: AI reads Tier 1 context in 30 seconds and picks up exactly where it left off. Quantify: 50 campaigns × 10 mins/session × 20 sessions = 167 hours saved/month. | J13: Before/After comparison card | K13: White Paper §3 context recovery time; ICP §4 pain points | L13: Calculate your own context recovery ROI | M13: Draft | N13: ROI hook for agency operators. Make the math undeniable.
A14: Apr 18, 2026 | B14: Fri | C14: 2 | D14: The Architecture | E14: Architecture | F14: All Segments | G14: Explainer / Thought Leadership | H14: Why Git is the best memory system for AI — and why no one talks about it. | I14: Contrarian take: everyone's building vector databases and RAG pipelines for AI memory. But git already solves version control, audit trails, portability, and team collaboration for human developers. AI Memory Brain just extends that to AI context. Human-readable, no proprietary formats, works offline, full diff history. The simplest solution wins. | J14: None — text post | K14: White Paper §9: Git as Persistence Layer innovation | L14: What memory architecture are you using today? | M14: Draft | N14: Contrarian angle. Good for thought leadership reach.
A15: WEEK 3 — COMPETITIVE: Why AI Memory Brain Wins
A16: Apr 21, 2026 | B16: Mon | C16: 3 | D16: Competitive | E16: Competitive | F16: Enterprise CTOs | G16: Comparison Post | H16: Mem0 vs. Zep vs. Letta vs. AI Memory Brain. A real comparison — not a sales pitch. | I16: Honest competitive breakdown. Mem0: great for single agents, adaptive multi-store memory. Zep: temporal knowledge graph, time-aware retrieval. Letta: self-editing memory blocks, persistent assistants. AI Memory Brain: only one with pre-built domain expertise across 20 departments, git-backed audit trail, non-technical deployment, and CC/DE governance. Be honest about where others win (retrieval speed, dev SDKs). Position where AMB wins: organizational memory for non-technical operators. | J16: Comparison table | K16: Competitive Analysis: 14 competitors profiled; ICP §8-9 | L16: Which memory solution are you evaluating? I'll give you a real comparison. | M16: Draft | N16: Honest = trusted. This builds authority with CTO segment.
A17: Apr 22, 2026 | B17: Tue | C17: 3 | D17: Competitive | E17: Competitive | F17: Operations Leaders | G17: Hot Take / Opinion Post | H17: ChatGPT Memory is for chatbots. AI Memory Brain is for businesses. Here's the difference. | I17: Foundation model native memory (ChatGPT, Claude, Gemini) solves personal memory — individual user preferences, conversation continuity. Zero cross-session organizational memory, no department structure, no audit trail, vendor lock-in. AI Memory Brain solves organizational memory — the knowledge your company accumulates across all AI interactions, all departments, all sessions. Different problem. Different solution. | J17: None — opinion post | K17: Competitive Analysis: Tier 1 Foundation model native memory | L17: Save if your ops team is relying on ChatGPT Memory for business context | M17: Draft | N17: Differentiates from the most recognized competitor.
A18: Apr 23, 2026 | B18: Wed | C18: 3 | D18: Competitive | E18: Competitive | F18: AI Agent Builders | G18: Niche Technical Post | H18: We don't use vector databases. Here's why that's actually a feature. | I18: Technical post for builders. Vector DBs: opaque retrieval, no human-readable audit trail, requires embedding pipelines, expensive at scale, can't be reviewed by a human. AI Memory Brain: Markdown files in Git. Diff history on every decision. Human-readable. Portable. Works with any LLM without retraining. 3-tier loading beats semantic search for structured project memory. Not anti-RAG — just a different tool for a different problem. | J18: None — technical text post | K18: White Paper §2: Why Existing Approaches Fall Short; §9 innovations | L18: Would you give up vector retrieval speed for full human-readable audit trails? | M18: Draft | N18: Niche but high-engagement with serious builders.
A19: Apr 24, 2026 | B19: Thu | C19: 3 | D19: Competitive | E19: Competitive | F19: B2B Lead Gen Operators | G19: Accessibility Post | H19: Most AI memory tools require a developer to set up. Ours requires Markdown. | I19: Pain point for agencies: they need powerful AI memory but don't have engineering teams to implement Mem0 or Zep. AI Memory Brain is file-based — any team member can read the context files, update them, and understand what the AI knows. No SDK. No API calls. No infrastructure. Deployed via Git. Runs in any AI client (Claude, ChatGPT, Gemini). This is the unfair advantage for non-technical operators. | J19: None — text post with contrast | K19: ICP §9: Where AI Memory Brain Wins; competitive analysis | L19: Does your agency have an engineering team to implement Mem0? | M19: Draft | N19: Non-technical deployment is a key differentiator for this segment.
A20: Apr 25, 2026 | B20: Fri | C20: 3 | D20: Competitive | E20: Competitive | F20: All Segments | G20: Vision / Thought Leadership | H20: The future of AI isn't personal memory. It's organizational memory. Here's what that looks like. | I20: Zoom out: personal AI memory (ChatGPT remembering your preferences) is useful but small. The real opportunity is organizational memory — every decision, every campaign result, every client interaction, every architectural choice accumulated and accessible to every AI session across the entire company. That's the next phase of AI adoption. The companies that build this first will have an insurmountable knowledge advantage. | J20: None — vision post | K20: White Paper executive summary; ICP analysis; Faruq conversation on acceleration to 2026 | L20: What would your company look like if your AI remembered everything? | M20: Draft | N20: End-of-week macro vision. High shareability.
A21: WEEK 4 — SOCIAL PROOF: Production Results
A22: Apr 28, 2026 | B22: Mon | C22: 4 | D22: Social Proof | E22: Social Proof | F22: Enterprise CTOs | G22: Results / Case Study | H22: 77 user stories. 22 sessions. 30+ architectural decision files. 0 open risks. Production AI memory in action. | I22: Deep dive into Sovrynty deployment. A zero-trust crypto financial platform managed across 2 major releases, 19 epics, 77 completed stories. All through AI_Memory. The AI tracked 14 APK versions, integrated Bridge.xyz, Openfort, deployed to Fly.io and Hetzner. Any new session can find prior decisions on Docker config, webhook state machines, FIDO2 auth in under 30 seconds via keyword index. This is production. Not demo. | J22: Key metrics table from white paper | K22: White Paper §7.1: Sovrynty deployment | L22: Ask me about deploying this for your AI infrastructure | M22: Draft | N22: Proof post — hardest to argue with. Sets production credibility.
A23: Apr 29, 2026 | B23: Tue | C23: 4 | D23: Social Proof | E23: Social Proof | F23: AI Agent Builders | G23: Technical Case Study | H23: Eve-oc: a 24/7 personal AI assistant running 4 different models through one memory layer. How we built it. | I23: Break down the Eve-oc deployment: OpenClaw framework, Docker on Hetzner, WhatsApp Business access, multi-model routing (Gemini Flash for standard, Gemini Pro for reasoning, Claude for code). Same AI Memory Brain architecture serves all four models through a unified context layer. This is model-agnostic design in production. One memory system, many models. | J23: Architecture diagram for Eve-oc multi-model routing | K23: White Paper §7.3: Eve-oc deployment | L23: Drop a comment if you're building multi-model agent systems | M23: Draft | N23: Highly relevant to agent builders evaluating multi-model architectures.
A24: Apr 30, 2026 | B24: Wed | C24: 4 | D24: Social Proof | E24: Social Proof | F24: Operations Leaders | G24: ROI / Metrics Post | H24: Context recovery time: 10–15 minutes → 30 seconds. That's what persistent AI memory does to your operations. | I24: Frame for ops leaders: every time your team starts an AI session on a complex workflow, they re-brief. Multiply that by your team × sessions × months. Then flip the math: with AI Memory Brain, the AI reads Tier 1 context in under 30 seconds. No re-briefing. No re-explaining. 22+ sessions logged on one project alone — all inheriting perfect state from the prior session. Here's what that looks like at scale. | J24: Time-saving calculation table | K24: White Paper §4.1, key metrics table | L24: Calculate your team's context recovery ROI — DM me the math | M24: Draft | N24: ROI framing for the ops segment decision-makers.
A25: May 1, 2026 | B25: Fri | C25: 4 | D25: Social Proof | E25: Social Proof | F25: All Segments | G25: Reflection / Community Post | H25: What I've learned from deploying AI memory across 3 production projects spanning crypto finance, AI context products, and multi-model personal assistants. | I25: Reflective post — personal learnings from the 3 deployments. Top lessons: 1) Closure protocol is more important than opening protocol. 2) The Tier 2 keyword index is the highest-leverage investment. 3) Git audit trails become invaluable at Session 10+. 4) Non-technical team members read and update the files — that's unexpected and powerful. 5) The system evolves the project; the project doesn't evolve the system. | J25: None — reflective text | K25: White Paper §8: System Evolution; Faruq conversation | L25: What's your most painful AI context lesson? Share below. | M25: Draft | N25: Authentic voice post — high trust-builder.
A26: WEEK 5 — ICP DEEP DIVE: AI Agent Builders
A27: May 5, 2026 | B27: Tue | C27: 5 | D27: ICP Deep Dive | E27: ICP Deep Dive | F27: AI Agent Builders | G27: Problem-Specific Post | H27: Your agents forget everything between sessions. Your clients pay for intelligence that evaporates every time the window closes. | I27: Direct address to agent builders. Name the specific pain: stateless agents in production. Demo agents work. Production agents fail because they can't handle multi-session complexity. Context window stuffing is expensive and unreliable. RAG helps but doesn't solve structured project memory. Every client engagement starts from zero. Then present the alternative: a 3-tier architecture running 51 agents in production. | J27: None — direct text | K27: ICP §6: AI Agent Builders segment; white paper §3 | L27: What's your current approach to agent memory across sessions? | M27: Draft | N27: Direct address post converts best for Tier 1 ICP.
A28: May 6, 2026 | B28: Wed | C28: 5 | D28: ICP Deep Dive | E28: ICP Deep Dive | F28: AI Agent Builders | G28: Technical Tutorial | H28: The 3-tier lazy-loading memory architecture: a system diagram every agent builder should see. | I28: Detailed technical walkthrough of the architecture. How to implement Tier 1 (always-read context files), Tier 2 (keyword index pattern), and Tier 3 (on-demand loading). Why this beats stuffing everything into the system prompt. How git becomes your persistence layer. Token math: Tier 1 <10K tokens, Tier 2 <1K tokens for 50+ decisions. Full project history, <5% context usage. | J28: Annotated 3-tier architecture diagram | K28: White Paper §3: AI_Memory Architecture | L28: Save this — share with your team before your next agent build | M28: Draft | N28: Technical depth post. Most saved/shared for this segment.
A29: May 7, 2026 | B29: Thu | C29: 5 | D29: ICP Deep Dive | E29: ICP Deep Dive | F29: AI Agent Builders | G29: Comparison Post | H29: LangMem vs. AI Memory Brain: what's the actual difference for production agents? | I29: Honest comparison: LangMem (LangChain's memory solution) uses rolling summarization and is tightly coupled to LangGraph. Great for conversational agents. Limited for complex multi-department project memory. AI Memory Brain: file-based, model-agnostic, git-backed, human-readable, works without LangChain dependency. Best use case for AI Memory Brain: multi-session production agents managing complex, structured project knowledge across departments. | J29: Side-by-side comparison table | K29: Competitive analysis: LangMem profile; ICP §6 | L29: Which memory approach is your production stack using? | M29: Draft | N29: Comparison posts drive high engagement from technical audience.
A30: May 8, 2026 | B30: Fri | C30: 5 | D30: ICP Deep Dive | E30: ICP Deep Dive | F30: AI Agent Builders | G30: CTA / Offer Post | H30: Free architecture review: does your agent stack need persistent memory? I'll tell you in 30 minutes. | I30: Direct CTA post. Offer: 30-minute free architecture review call for agent builders. What I'll cover: current memory approach assessment, where persistent memory would add the most value, 3 quick wins to implement this week. Soft pitch: for teams that want full implementation, we offer an architecture consultation package. Scarcity: 5 spots this month. | J30: None — clean CTA post | K30: ICP §10: Tier 1 immediate target; §11 outreach strategy | L30: DM me 'MEMORY AUDIT' to book your spot | M30: Draft | N30: Conversion post. End of segment week with clear CTA.
A31: WEEK 6 — ICP DEEP DIVE: B2B Lead Gen Operators
A32: May 11, 2026 | B32: Mon | C32: 6 | D32: ICP Deep Dive | E32: ICP Deep Dive | F32: B2B Lead Gen Operators | G32: ROI Hook Post | H32: You're running 50 client campaigns. Your AI starts completely fresh on every single one. | I32: Lead gen specific pain: 50 campaigns, each with unique ICP definitions, brand voice, winning copy angles, objection handling, reply patterns — and AI has zero memory of any of it. Every session: re-explain. Every session: re-train. Every session: start from scratch. The competitor running AI Memory Brain has all of that stored and instantly loadable. Which agency would you rather be? | J32: None — punchy text post | K32: ICP §4: B2B Lead Gen segment; Faruq conversation campaign context | L32: Tag an agency owner who's running AI without persistent memory | M32: Draft | N32: Agency-to-agency angle. High tagging potential.
A33: May 12, 2026 | B33: Tue | C33: 6 | D33: ICP Deep Dive | E33: ICP Deep Dive | F33: B2B Lead Gen Operators | G33: Framework Post | H33: The campaign memory stack: how we store 12 months of campaign intelligence so it never gets lost. | I33: Practical framework post. What to store in campaign memory: ICP definition (company size, title, pain points, triggers), winning copy angles (subject lines, opening hooks, CTAs), reply patterns (what response types indicate buying intent), objection handling (top 5 objections + proven responses), competitive intel (what works vs. each competitor). How the 3-tier system loads it: Tier 1 for active client context, Tier 3 for historical archives. | J33: Campaign memory stack diagram | K33: ICP §4 pain points; white paper §3 architecture applied to lead gen | L33: Save this framework for your next campaign setup | M33: Draft | N33: Highly practical. Best post for agency bookmarks.
A34: May 13, 2026 | B34: Wed | C34: 6 | D34: ICP Deep Dive | E34: ICP Deep Dive | F34: B2B Lead Gen Operators | G34: Storytelling Post | H34: What running 50 client campaigns with persistent AI memory actually looks like after 90 days. | I34: Narrative/projection format. Day 1: AI knows nothing, you manually brief every campaign. Day 30: AI has all 50 client ICPs, brand voices, and initial results loaded. Day 60: AI starts identifying patterns across campaigns — what works in SaaS vs. recruiting vs. real estate. Day 90: AI personalizes outreach at a level no stateless system can match because it actually remembers what's worked. This is the compounding advantage. | J34: Timeline progression graphic | K34: ICP §4: cross-campaign learning pain point; white paper compounding cost framing | L34: Where are you in this 90-day progression? | M34: Draft | N34: Shows compounding value over time — key for justifying implementation cost.
A35: May 15, 2026 | B35: Fri | C35: 6 | D35: ICP Deep Dive | E35: ICP Deep Dive | F35: B2B Lead Gen Operators | G35: CTA Post | H35: Campaign memory audit: free 30-minute call. I'll map exactly where your agency is losing campaign intelligence. | I35: Direct CTA for lead gen operators. What we cover: current AI toolstack assessment, where campaign memory is leaking, 3 immediate wins for persistent campaign context, ROI estimate for your specific campaign volume. Ironic positioning: reach out via cold message to book an audit about better cold outreach. 5 spots available. | J35: None — clean CTA | K35: ICP §11 outreach strategy for B2B Lead Gen | L35: DM me 'CAMPAIGN AUDIT' to claim a spot | M35: Draft | N35: End-of-week CTA. Lean into the irony for this segment.
A36: WEEK 7 — ICP DEEP DIVE: Operations Leaders / RevOps
A37: May 18, 2026 | B37: Mon | C37: 7 | D37: ICP Deep Dive | E37: ICP Deep Dive | F37: Operations Leaders | G37: Problem Post | H37: Your Salesforce has the data. Your AI has the intelligence. They don't talk to each other. And your team pays for that disconnect every day. | I37: Ops leader specific pain: CRM has deal history, call recordings, pipeline data. AI (ChatGPT, Claude, Copilot) has the ability to analyze, summarize, recommend. But they don't share memory. Every analyst re-loads the same data. No memory of why last quarter's enterprise deals stalled at legal. No memory of seasonal patterns that repeat every year. No memory of why specific reps over/underperform. AI Memory Brain bridges this gap — organizational memory that connects your data to your AI intelligence. | J37: None — text post | K37: ICP §5: Operations Leaders segment pain points | L37: What's the most expensive data-AI disconnect in your ops stack? | M37: Draft | N37: Opens the RevOps week with a sharp pain-point hook.
A38: May 19, 2026 | B38: Tue | C38: 7 | D38: ICP Deep Dive | E38: ICP Deep Dive | F38: Operations Leaders | G38: Solution Post | H38: What 51 domain agents across Sales, Marketing, Finance, Operations, and Legal actually looks like in production. | I38: Detailed breakdown of the departmental structure. Each department has dedicated agents with persistent memory of that domain's context, decisions, and accumulated intelligence. Sales agent: win/loss patterns, rep behavior profiles, deal velocity history. Finance agent: budget decisions, model assumptions, cash flow patterns. Legal agent: contract risk patterns, negotiation history, compliance decisions. All coordinated under CCDE governance. This is organizational AI memory. | J38: Department map visualization | K38: White Paper §5: Departmental Organization; ICP §5 | L38: Which department would benefit most from persistent AI memory in your org? | M38: Draft | N38: High-value visual post for ops leaders.
A39: May 20, 2026 | B39: Wed | C39: 7 | D39: ICP Deep Dive | E39: ICP Deep Dive | F39: Operations Leaders | G39: Governance Post | H39: The CCDE Standard: military-inspired AI governance for business operations. | I39: Explain Centralized Command, Decentralized Execution for a business audience. The insight from Faruq's conversation: organizational standards live at the root level (centralized), but each project folder gets its own copy of those standards and can evolve them locally (decentralized execution). This prevents organizational drift while allowing project-level adaptation. For ops leaders: this is how you govern AI across 20 departments without everything becoming a committee. | J39: CCDE structure diagram | K39: Faruq Hunter conversation: CCDE discussion; ICP §5 | L39: Does your ops team have a governance model for AI decision-making? | M39: Draft | N39: Unique angle — governance-focused ops leaders will engage.
A40: May 22, 2026 | B40: Fri | C40: 7 | D40: ICP Deep Dive | E40: ICP Deep Dive | F40: Operations Leaders | G40: CTA Post | H40: Department AI readiness assessment: free for operations leaders. Find out what your ops stack is actually retaining across AI sessions. | I40: Structured CTA. What the assessment covers: current AI toolstack audit across departments, where institutional knowledge is being lost, which departments are highest-priority for AI memory implementation, estimated ROI for your specific team size and session frequency. Offer: free 45-minute assessment, 3 deliverables (current state map, gap analysis, quick win roadmap). 3 spots this month. | J40: None — CTA post | K40: ICP §10-11: Tier 1 target, outreach strategy for Ops Leaders | L40: DM me 'OPS ASSESSMENT' to book your evaluation | M40: Draft | N40: End-of-week CTA for highest-LTV segment.
...

Sheet Content Pillars
A1: AI Memory Brain — Content Pillars & Messaging Framework
A2: Pillar | B2: Colour Code | C2: Core Message | D2: Best For (ICP) | E2: Key Hook Formula | F2: Primary Source Material | G2: Sample CTA
A3: Context Rot | B3: #FFE5B4 | C3: Every AI session starts with total amnesia. The cost of stateless AI compounds with every session. | D3: All Segments | E3: [Quantified pain] → [Frequency] → [Compounding cost] | F3: White Paper §1: The Hidden Flaw; §1.2 Compounding Cost | G3: Calculate your context recovery cost
A4: Architecture | B4: #B4D4FF | C4: 3-tier lazy loading + session lifecycle + departmental organization = AI that gets smarter every session. | D4: AI Agent Builders, Enterprise CTOs | E4: [Technical innovation] → [Why it beats X] → [Production proof] | F4: White Paper §3: Architecture; §4: Session Lifecycle; §5: Departmental Org | G4: Book a technical architecture walkthrough
A5: Social Proof | B5: #B4FFB4 | C5: 77 user stories. 22 sessions. 30+ decision files. 0 open risks. Not a demo — production. | D5: Enterprise CTOs, Operations Leaders | E5: [Specific metric] → [What it represents] → [Contrast: most solutions are still beta] | F5: White Paper §7: 3 Live Deployments (Sovrynty, Total Reqall, Eve-oc) | G5: Ask about deploying this for your team
A6: Competitive | B6: #FFB4B4 | C6: AI Memory Brain is the only solution with pre-built domain expertise across 20 departments. Everyone else makes you build from scratch. | D6: Enterprise CTOs, AI Agent Builders | E6: [Name the alternative] → [Honest comparison] → [Where AMB uniquely wins] | F6: Competitive Analysis: 14 competitors; ICP §8-9 | G6: I'll give you a real comparison — no sales pitch
A7: Thought Leadership | B7: #E8B4FF | C7: The future of AI is organizational memory, not personal memory. The companies that build this first win. | D7: All Segments | E7: [Contrarian insight] → [Why the crowd is wrong] → [What you should actually do] | F7: Faruq Hunter conversation; White Paper §10: Conclusion | G7: Follow to watch this get built in real time
A8: Product | B8: #FFE0B4 | C8: 150 MB. Portable. Works with any LLM. No engineering team required. This is what AI memory should be. | D8: B2B Lead Gen, Operations Leaders, Community Builders | E8: [Simple, tangible feature] → [Who it unlocks access for] → [Vs. complex alternatives] | F8: Faruq conversation: low memory footprint, browser extension, non-technical deployment | G8: Join the early access waitlist
A9: ICP Deep Dive | B9: #B4FFEE | C9: Segment-specific content that speaks directly to each ICP's exact pain, using their exact language. | D9: Rotates by segment (see calendar) | E9: [Direct address to role] → [Name their specific pain] → [Show the specific fix] | F9: ICP Analysis §3-7: all five segments; §11 messaging strategy | G9: DM me [SEGMENT-SPECIFIC KEYWORD] to get started

Sheet ICP Quick Reference
A1: AI Memory Brain — ICP Segment Quick Reference
A2: ICP Segment | B2: Priority Tier | C2: Title Patterns | D2: Core Pain (AI Memory) | E2: Value Prop Hook | F2: Best Post Format | G2: LinkedIn CTA Keyword | H2: LTV Range
A3: AI Agent Builders | B3: TIER 1 (Month 1-3) | C3: AI Agent Dev, Automation Consultant, AI Solutions Architect, AI Agency Founder | D3: Stateless agents in production. Client-specific context, learned preferences, accumulated knowledge — all lost every session. Multi-session complexity kills production reliability. | E3: Stop building memory from scratch for every client. Deploy a 3-tier architecture running 51 agents in production today. | F3: Technical deep-dive, System diagrams, Before/After case studies | G3: MEMORY AUDIT | H3: $15K–$50K
A4: B2B Lead Gen Operators | B4: TIER 1 (Month 1-3) | C4: B2B Lead Gen Specialist, Cold Email Expert, AI Outreach Consultant, Growth Agency Founder | D4: Running 50+ client campaigns and AI treats every email like it's the first one. Zero memory of ICP, winning copy angles, reply patterns, or objection handling across sessions. | E4: Each campaign gets its own persistent memory — ICP definitions, winning copy, reply patterns — so your AI gets smarter with every send. | F4: ROI calculators, Campaign performance comparisons, Framework posts | G4: CAMPAIGN AUDIT | H4: $25K–$50K
A5: Operations Leaders | B5: TIER 1 (Month 1-3) | C5: VP Revenue Operations, Director of Operations, Head of GTM, RevOps Manager, CRO | D5: Institutional knowledge in people's heads. AI analyzes data without remembering why deals were won/lost, seasonal patterns, or which processes are current vs. outdated. | E5: 51 domain agents across Sales, Marketing, Finance, Operations, Legal — accumulating intelligence over time. Your AI doesn't just process data. It remembers context. | F5: Operational frameworks, Governance posts, Enterprise ROI models | G5: OPS ASSESSMENT | H5: $50K–$100K+
A6: Enterprise CTOs | B6: TIER 2 (Month 3-6) | C6: CTO, VP Engineering, Head of AI/ML, Chief AI Officer, Director of Platform Engineering | D6: Evaluating 10 memory solutions with no clear winner. Vendor lock-in risk. Compliance/audit needs. Multi-department deployment complexity. Production readiness uncertainty. | E6: You're evaluating Mem0, Zep, and Letta. Here's what none of them solve: organizational memory across 20 departments with a git-backed audit trail and zero vendor lock-in. | F6: Comparison tables, Technical architecture posts, Whitepapers | G6: ARCHITECTURE BRIEF | H6: $100K+
A7: Community Builders | B7: TIER 2 (Month 3-6) | C7: AI Educator, AI Advocate, Community Builder, Newsletter Creator | D7: Content fatigue from re-researching the same topics. No AI memory of prior community interactions, subscriber segments, or what content resonated with which audience. | E7: Your newsletter AI forgets your audience every session. AI Memory Brain gives your content operation persistent memory of brand voice, audience data, and content history. | F7: Behind-the-scenes, Community case studies, Co-created content | G7: CONTENT COLLAB | H7: $5K–$15K + awareness

Sheet Summary
A1: Content Calendar Summary
A3: METRIC | B3: VALUE
A4: Total Posts Planned | B4: 36
A5: Weeks Covered | B5: 8 (Apr 7 – May 30, 2026)
A6: Avg Posts per Week | B6: ~4.5
A7: Platform | B7: LinkedIn (primary)
A9: BY ICP SEGMENT | B9: # Posts | C9: % of Total
A10: AI Agent Builders | B10: =COUNTIF('LinkedIn Content Calendar'!F:F,"AI Agent Builders") -> 8 | C10: =B10/B4 -> 0.22222222
A11: B2B Lead Gen Operators | B11: =COUNTIF('LinkedIn Content Calendar'!F:F,"B2B Lead Gen Operators") -> 7 | C11: =B11/B4 -> 0.19444444
A12: Operations Leaders | B12: =COUNTIF('LinkedIn Content Calendar'!F:F,"Operations Leaders") -> 8 | C12: =B12/B4 -> 0.22222222
A13: Enterprise CTOs | B13: =COUNTIF('LinkedIn Content Calendar'!F:F,"Enterprise CTOs") -> 3 | C13: =B13/B4 -> 0.083333333
A14: Community Builders | B14: =COUNTIF('LinkedIn Content Calendar'!F:F,"Community Builders") -> 0 | C14: =B14/B4 -> 0
A15: All Segments | B15: =COUNTIF('LinkedIn Content Calendar'!F:F,"All Segments") -> 9 | C15: =B15/B4 -> 0.25
A17: BY CONTENT PILLAR | B17: # Posts
A18: Context Rot | B18: =COUNTIF('LinkedIn Content Calendar'!E:E,"Context Rot") -> 5
A19: Architecture | B19: =COUNTIF('LinkedIn Content Calendar'!E:E,"Architecture") -> 5
A20: Social Proof | B20: =COUNTIF('LinkedIn Content Calendar'!E:E,"Social Proof") -> 4
A21: Competitive | B21: =COUNTIF('LinkedIn Content Calendar'!E:E,"Competitive") -> 5
A22: Thought Leadership | B22: =COUNTIF('LinkedIn Content Calendar'!E:E,"Thought Leadership") -> 3
A23: Product | B23: =COUNTIF('LinkedIn Content Calendar'!E:E,"Product") -> 1
A24: ICP Deep Dive | B24: =COUNTIF('LinkedIn Content Calendar'!E:E,"ICP Deep Dive") -> 12
A26: BY POST FORMAT | B26: # Posts
A27: Text Post | B27: =COUNTIF('LinkedIn Content Calendar'!G:G,"Text Post") -> 1
A28: Framework Post | B28: =COUNTIF('LinkedIn Content Calendar'!G:G,"Framework Post") -> 2
A29: Comparison Post | B29: =COUNTIF('LinkedIn Content Calendar'!G:G,"Comparison Post") -> 2
A30: Storytelling Post | B30: =COUNTIF('LinkedIn Content Calendar'!G:G,"Storytelling Post") -> 2
A31: CTA Post | B31: =COUNTIF('LinkedIn Content Calendar'!G:G,"CTA Post") -> 2
A32: Carousel / Infographic | B32: =COUNTIF('LinkedIn Content Calendar'!G:G,"Carousel / Infographic") -> 1
A33: Technical Deep Dive | B33: =COUNTIF('LinkedIn Content Calendar'!G:G,"Technical Deep Dive") -> 1
