Workbook

Sheet Cover
B2: MSIFS — Frontier Impact Infrastructure & Minerals Fund
B3: Multi-Dimensional Infrastructure Project Finance Model
B5: Model Version 1.0 | February 2026
B9: MODEL ARCHITECTURE
B10: Sheet | C10: Purpose
B11: 1. Cover | C11: This page — overview and instructions
B12: 2. Assumptions | C12: All hardcoded inputs: project type toggles, macro assumptions, financing terms
B13: 3. Revenue Build | C13: Revenue projections by project type with commodity price scenarios
B14: 4. CAPEX Schedule | C14: Construction & development cost phasing with contingency
B15: 5. OPEX Schedule | C15: Operating cost buildup with escalation and FX impact
B16: 6. Financing Structure | C16: Multi-tranche debt & equity waterfall with currency layers
B17: 7. Cash Flow Waterfall | C17: Integrated cash flow statement with DSCR and LLCR
B18: 8. Currency & FX | C18: Cross-border FX modeling, hedging costs, local currency swaps
B19: 9. Returns Analysis | C19: IRR, NPV, MOIC, payback for equity and project-level returns
B20: 10. Exit Scenarios | C20: Multiple exit paths: trade sale, IPO, recap, strategic, liquidation
B21: 11. Sensitivity | C21: Tornado charts data, scenario matrix, Monte Carlo input ranges
B22: 12. Impact Metrics | C22: IRIS+ aligned impact KPIs and impact-linked carry calculation
B24: COLOR CODING CONVENTIONS
B25: Blue text | C25: Hardcoded inputs — user modifiable
B26: Black text | C26: Formulas and calculations
B27: Green text | C27: Cross-sheet references
B28: Yellow highlight | C28: Key assumptions requiring attention

Sheet Assumptions
B1: GLOBAL ASSUMPTIONS & PROJECT PARAMETERS
B3: PROJECT TYPE SELECTOR
B4: Project Type Toggle (1-6) | C4: 1
B5: 1 = Port & Logistics Infrastructure | C5: Lamu Port, Maputo, Grain Elevators
B6: 2 = Mining & Mineral Processing | C6: Lithium, Copper, Rare Earth, Gold
B7: 3 = Energy & Power Generation | C7: Solar, Wind, Hybrid, Gas-to-Power
B8: 4 = Transport Corridors | C8: Toll Roads, Railways, LAPSSET
B9: 5 = LNG & Gas Infrastructure | C9: Mtwara LNG, Virtual Pipelines, CNG
B10: 6 = Agri-Processing & Value Chain | C10: Grain Handling, Cold Storage, Fertilizer
B12: MACRO & COUNTRY ASSUMPTIONS
B13: Parameter | C13: Base Case | D13: Downside | E13: Upside | F13: Unit
B14: Country Risk Premium | C14: 0.045 | D14: 0.065 | E14: 0.03 | F14: %
B15: Sovereign Credit Spread (bps) | C15: 350 | D15: 550 | E15: 200 | F15: bps
B16: Local Inflation Rate | C16: 0.07 | D16: 0.12 | E16: 0.04 | F16: %
B17: USD Inflation Rate | C17: 0.025 | D17: 0.04 | E17: 0.02 | F17: %
B18: Local Currency Depr. Rate (annual) | C18: 0.05 | D18: 0.1 | E18: 0.02 | F18: %
B19: Political Risk Insurance Cost | C19: 0.015 | D19: 0.025 | E19: 0.01 | F19: %
B20: Corporate Tax Rate (host) | C20: 0.3 | D20: 0.35 | E20: 0.25 | F20: %
B21: Withholding Tax on Dividends | C21: 0.1 | D21: 0.15 | E21: 0.05 | F21: %
B22: VAT Rate | C22: 0.16 | D22: 0.18 | E22: 0.14 | F22: %
B23: Tax Holiday (years) | C23: 5 | D23: 0 | E23: 10 | F23: yrs
B24: WACC — Risk-Free Rate (USD) | C24: 0.045 | D24: 0.055 | E24: 0.035 | F24: %
B25: Equity Risk Premium | C25: 0.065 | D25: 0.085 | E25: 0.05 | F25: %
B26: Target Gross IRR | C26: 0.17 | D26: 0.13 | E26: 0.22 | F26: %
B28: PROJECT-LEVEL ASSUMPTIONS
B29: Parameter | C29: Base Case | D29: Downside | E29: Upside | F29: Unit
B30: Total Project Cost ($M) | C30: 50 | D30: 30 | E30: 100 | F30: $M
B31: Construction Period (months) | C31: 24 | D31: 36 | E31: 18 | F31: mo
B32: Operating Life (years) | C32: 20 | D32: 15 | E32: 25 | F32: yrs
B33: Fund Investment ($M) | C33: 15 | D33: 8 | E33: 25 | F33: $M
B34: Equity Stake (%) | C34: 0.3 | D34: 0.2 | E34: 0.49 | F34: %
B35: Revenue Ramp-Up (years to full) | C35: 3 | D35: 5 | E35: 2 | F35: yrs
B36: Steady-State Utilization | C36: 0.85 | D36: 0.7 | E36: 0.95 | F36: %
B37: Annual Revenue at Full Capacity ($M) | C37: 25 | D37: 15 | E37: 40 | F37: $M
B38: OPEX as % of Revenue | C38: 0.45 | D38: 0.55 | E38: 0.35 | F38: %
B39: Annual OPEX Escalation | C39: 0.04 | D39: 0.07 | E39: 0.025 | F39: %
B40: Maintenance CAPEX (% of initial) | C40: 0.02 | D40: 0.035 | E40: 0.015 | F40: %
B41: Working Capital (days of revenue) | C41: 60 | D41: 90 | E41: 45 | F41: days
B42: Contingency (% of CAPEX) | C42: 0.1 | D42: 0.15 | E42: 0.05 | F42: %
B44: FINANCING STRUCTURE
...

Sheet Revenue Build
B1: REVENUE PROJECTIONS — 20-YEAR OPERATING HORIZON
B3: Year | C3: Unit | D3: 1 | E3: 2 | F3: 3 | G3: 4 | H3: 5 | I3: 6 | J3: 7 | K3: 8 | L3: 9 | M3: 10 | N3: 11 | O3: 12 | P3: 13 | Q3: 14 | R3: 15 | S3: 16 | T3: 17 | U3: 18 | V3: 19 | W3: 20
B4: REVENUE DRIVERS
B5: Capacity Utilization Ramp | C5: % | D5: =IF(1<=Assumptions!C31/12,0,MIN(Assumptions!C36,MAX(0,1-Assumptions!C31/12)/Assumptions!C35)) -> 0 | E5: =IF(2<=Assumptions!C31/12,0,MIN(Assumptions!C36,MAX(0,2-Assumptions!C31/12)/Assumptions!C35)) -> 0 | F5: =IF(3<=Assumptions!C31/12,0,MIN(Assumptions!C36,MAX(0,3-Assumptions!C31/12)/Assumptions!C35)) -> 0.33333333 | G5: =IF(4<=Assumptions!C31/12,0,MIN(Assumptions!C36,MAX(0,4-Assumptions!C31/12)/Assumptions!C35)) -> 0.66666667 | H5: =IF(5<=Assumptions!C31/12,0,MIN(Assumptions!C36,MAX(0,5-Assumptions!C31/12)/Assumptions!C35)) -> 0.85 | I5: =IF(6<=Assumptions!C31/12,0,MIN(Assumptions!C36,MAX(0,6-Assumptions!C31/12)/Assumptions!C35)) -> 0.85 | J5: =IF(7<=Assumptions!C31/12,0,MIN(Assumptions!C36,MAX(0,7-Assumptions!C31/12)/Assumptions!C35)) -> 0.85 | K5: =IF(8<=Assumptions!C31/12,0,MIN(Assumptions!C36,MAX(0,8-Assumptions!C31/12)/Assumptions!C35)) -> 0.85 | L5: =IF(9<=Assumptions!C31/12,0,MIN(Assumptions!C36,MAX(0,9-Assumptions!C31/12)/Assumptions!C35)) -> 0.85 | M5: =IF(10<=Assumptions!C31/12,0,MIN(Assumptions!C36,MAX(0,10-Assumptions!C31/12)/Assumptions!C35)) -> 0.85 | N5: =IF(11<=Assumptions!C31/12,0,MIN(Assumptions!C36,MAX(0,11-Assumptions!C31/12)/Assumptions!C35)) -> 0.85 | O5: =IF(12<=Assumptions!C31/12,0,MIN(Assumptions!C36,MAX(0,12-Assumptions!C31/12)/Assumptions!C35)) -> 0.85 | P5: =IF(13<=Assumptions!C31/12,0,MIN(Assumptions!C36,MAX(0,13-Assumptions!C31/12)/Assumptions!C35)) -> 0.85 | Q5: =IF(14<=Assumptions!C31/12,0,MIN(Assumptions!C36,MAX(0,14-Assumptions!C31/12)/Assumptions!C35)) -> 0.85 | R5: =IF(15<=Assumptions!C31/12,0,MIN(Assumptions!C36,MAX(0,15-Assumptions!C31/12)/Assumptions!C35)) -> 0.85 | S5: =IF(16<=Assumptions!C31/12,0,MIN(Assumptions!C36,MAX(0,16-Assumptions!C31/12)/Assumptions!C35)) -> 0.85 | T5: =IF(17<=Assumptions!C31/12,0,MIN(Assumptions!C36,MAX(0,17-Assumptions!C31/12)/Assumptions!C35)) -> 0.85 | U5: =IF(18<=Assumptions!C31/12,0,MIN(Assumptions!C36,MAX(0,18-Assumptions!C31/12)/Assumptions!C35)) -> 0.85 | V5: =IF(19<=Assumptions!C31/12,0,MIN(Assumptions!C36,MAX(0,19-Assumptions!C31/12)/Assumptions!C35)) -> 0.85 | W5: =IF(20<=Assumptions!C31/12,0,MIN(Assumptions!C36,MAX(0,20-Assumptions!C31/12)/Assumptions!C35)) -> 0.85
B6: Gross Revenue (Base, $M) | C6: $M | D6: =Assumptions!C37*D5 -> 0 | E6: =Assumptions!C37*E5 -> 0 | F6: =Assumptions!C37*F5 -> 8.3333333 | G6: =Assumptions!C37*G5 -> 16.666667 | H6: =Assumptions!C37*H5 -> 21.25 | I6: =Assumptions!C37*I5 -> 21.25 | J6: =Assumptions!C37*J5 -> 21.25 | K6: =Assumptions!C37*K5 -> 21.25 | L6: =Assumptions!C37*L5 -> 21.25 | M6: =Assumptions!C37*M5 -> 21.25 | N6: =Assumptions!C37*N5 -> 21.25 | O6: =Assumptions!C37*O5 -> 21.25 | P6: =Assumptions!C37*P5 -> 21.25 | Q6: =Assumptions!C37*Q5 -> 21.25 | R6: =Assumptions!C37*R5 -> 21.25 | S6: =Assumptions!C37*S5 -> 21.25 | T6: =Assumptions!C37*T5 -> 21.25 | U6: =Assumptions!C37*U5 -> 21.25 | V6: =Assumptions!C37*V5 -> 21.25 | W6: =Assumptions!C37*W5 -> 21.25
B7: Commodity Price Adjustment Factor | C7: x | D7: =IF(D5=0,0,(1+Assumptions!C70)^MAX(0,1-Assumptions!C31/12)) -> 0 | E7: =IF(E5=0,0,(1+Assumptions!C70)^MAX(0,2-Assumptions!C31/12)) -> 0 | F7: =IF(F5=0,0,(1+Assumptions!C70)^MAX(0,3-Assumptions!C31/12)) -> 1.02 | G7: =IF(G5=0,0,(1+Assumptions!C70)^MAX(0,4-Assumptions!C31/12)) -> 1.0404 | H7: =IF(H5=0,0,(1+Assumptions!C70)^MAX(0,5-Assumptions!C31/12)) -> 1.061208 | I7: =IF(I5=0,0,(1+Assumptions!C70)^MAX(0,6-Assumptions!C31/12)) -> 1.0824322 | J7: =IF(J5=0,0,(1+Assumptions!C70)^MAX(0,7-Assumptions!C31/12)) -> 1.1040808 | K7: =IF(K5=0,0,(1+Assumptions!C70)^MAX(0,8-Assumptions!C31/12)) -> 1.1261624 | L7: =IF(L5=0,0,(1+Assumptions!C70)^MAX(0,9-Assumptions!C31/12)) -> 1.1486857 | M7: =IF(M5=0,0,(1+Assumptions!C70)^MAX(0,10-Assumptions!C31/12)) -> 1.1716594 | N7: =IF(N5=0,0,(1+Assumptions!C70)^MAX(0,11-Assumptions!C31/12)) -> 1.1950926 | O7: =IF(O5=0,0,(1+Assumptions!C70)^MAX(0,12-Assumptions!C31/12)) -> 1.2189944 | P7: =IF(P5=0,0,(1+Assumptions!C70)^MAX(0,13-Assumptions!C31/12)) -> 1.2433743 | Q7: =IF(Q5=0,0,(1+Assumptions!C70)^MAX(0,14-Assumptions!C31/12)) -> 1.2682418 | R7: =IF(R5=0,0,(1+Assumptions!C70)^MAX(0,15-Assumptions!C31/12)) -> 1.2936066 | S7: =IF(S5=0,0,(1+Assumptions!C70)^MAX(0,16-Assumptions!C31/12)) -> 1.3194788 | T7: =IF(T5=0,0,(1+Assumptions!C70)^MAX(0,17-Assumptions!C31/12)) -> 1.3458683 | U7: =IF(U5=0,0,(1+Assumptions!C70)^MAX(0,18-Assumptions!C31/12)) -> 1.3727857 | V7: =IF(V5=0,0,(1+Assumptions!C70)^MAX(0,19-Assumptions!C31/12)) -> 1.4002414 | W7: =IF(W5=0,0,(1+Assumptions!C70)^MAX(0,20-Assumptions!C31/12)) -> 1.4282462
B8: FX-Adjusted Revenue ($M, USD) | C8: $M | D8: =IF(D5=0,0,D6*D7*('Currency & FX'!D11+'Currency & FX'!D12*(1/(1+Assumptions!C18)^MAX(0,1-Assumptions!C31/12)))) -> 0 | E8: =IF(E5=0,0,E6*E7*('Currency & FX'!E11+'Currency & FX'!E12*(1/(1+Assumptions!C18)^MAX(0,2-Assumptions!C31/12)))) -> 0 | F8: =IF(F5=0,0,F6*F7*('Currency & FX'!F11+'Currency & FX'!F12*(1/(1+Assumptions!C18)^MAX(0,3-Assumptions!C31/12)))) -> 8.3380952 | G8: =IF(G5=0,0,G6*G7*('Currency & FX'!G11+'Currency & FX'!G12*(1/(1+Assumptions!C18)^MAX(0,4-Assumptions!C31/12)))) -> 16.695156 | H8: =IF(H5=0,0,H6*H7*('Currency & FX'!H11+'Currency & FX'!H12*(1/(1+Assumptions!C18)^MAX(0,5-Assumptions!C31/12)))) -> 21.322449 | I8: =IF(I5=0,0,I6*I7*('Currency & FX'!I11+'Currency & FX'!I12*(1/(1+Assumptions!C18)^MAX(0,6-Assumptions!C31/12)))) -> 21.370427 | J8: =IF(J5=0,0,J6*J7*('Currency & FX'!J11+'Currency & FX'!J12*(1/(1+Assumptions!C18)^MAX(0,7-Assumptions!C31/12)))) -> 21.430178 | K8: =IF(K5=0,0,K6*K7*('Currency & FX'!K11+'Currency & FX'!K12*(1/(1+Assumptions!C18)^MAX(0,8-Assumptions!C31/12)))) -> 21.501629 | L8: =IF(L5=0,0,L6*L7*('Currency & FX'!L11+'Currency & FX'!L12*(1/(1+Assumptions!C18)^MAX(0,9-Assumptions!C31/12)))) -> 21.584713 | M8: =IF(M5=0,0,M6*M7*('Currency & FX'!M11+'Currency & FX'!M12*(1/(1+Assumptions!C18)^MAX(0,10-Assumptions!C31/12)))) -> 21.679371 | N8: =IF(N5=0,0,N6*N7*('Currency & FX'!N11+'Currency & FX'!N12*(1/(1+Assumptions!C18)^MAX(0,11-Assumptions!C31/12)))) -> 21.785553 | O8: =IF(O5=0,0,O6*O7*('Currency & FX'!O11+'Currency & FX'!O12*(1/(1+Assumptions!C18)^MAX(0,12-Assumptions!C31/12)))) -> 21.903212 | P8: =IF(P5=0,0,P6*P7*('Currency & FX'!P11+'Currency & FX'!P12*(1/(1+Assumptions!C18)^MAX(0,13-Assumptions!C31/12)))) -> 22.032312 | Q8: =IF(Q5=0,0,Q6*Q7*('Currency & FX'!Q11+'Currency & FX'!Q12*(1/(1+Assumptions!C18)^MAX(0,14-Assumptions!C31/12)))) -> 22.172821 | R8: =IF(R5=0,0,R6*R7*('Currency & FX'!R11+'Currency & FX'!R12*(1/(1+Assumptions!C18)^MAX(0,15-Assumptions!C31/12)))) -> 22.324716 | S8: =IF(S5=0,0,S6*S7*('Currency & FX'!S11+'Currency & FX'!S12*(1/(1+Assumptions!C18)^MAX(0,16-Assumptions!C31/12)))) -> 22.487979 | T8: =IF(T5=0,0,T6*T7*('Currency & FX'!T11+'Currency & FX'!T12*(1/(1+Assumptions!C18)^MAX(0,17-Assumptions!C31/12)))) -> 22.6626 | U8: =IF(U5=0,0,U6*U7*('Currency & FX'!U11+'Currency & FX'!U12*(1/(1+Assumptions!C18)^MAX(0,18-Assumptions!C31/12)))) -> 22.848574 | V8: =IF(V5=0,0,V6*V7*('Currency & FX'!V11+'Currency & FX'!V12*(1/(1+Assumptions!C18)^MAX(0,19-Assumptions!C31/12)))) -> 23.045904 | W8: =IF(W5=0,0,W6*W7*('Currency & FX'!W11+'Currency & FX'!W12*(1/(1+Assumptions!C18)^MAX(0,20-Assumptions!C31/12)))) -> 23.254599
B10: OPERATING REVENUE DETAIL
B11: Primary Revenue Stream ($M) | C11: $M | D11: =IF(D5=0,0,D8*0.85) -> 0 | E11: =IF(E5=0,0,E8*0.85) -> 0 | F11: =IF(F5=0,0,F8*0.85) -> 7.087381 | G11: =IF(G5=0,0,G8*0.85) -> 14.190883 | H11: =IF(H5=0,0,H8*0.85) -> 18.124081 | I11: =IF(I5=0,0,I8*0.85) -> 18.164863 | J11: =IF(J5=0,0,J8*0.85) -> 18.215651 | K11: =IF(K5=0,0,K8*0.85) -> 18.276384 | ... W11: =IF(W5=0,0,W8*0.85) -> 19.766409
B12: Secondary/By-product Revenue ($M) | C12: $M | D12: =IF(D5=0,0,D8*0.1) -> 0 | E12: =IF(E5=0,0,E8*0.1) -> 0 | F12: =IF(F5=0,0,F8*0.1) -> 0.83380952 | G12: =IF(G5=0,0,G8*0.1) -> 1.6695156 | H12: =IF(H5=0,0,H8*0.1) -> 2.1322449 | I12: =IF(I5=0,0,I8*0.1) -> 2.1370427 | J12: =IF(J5=0,0,J8*0.1) -> 2.1430178 | K12: =IF(K5=0,0,K8*0.1) -> 2.1501629 | ... W12: =IF(W5=0,0,W8*0.1) -> 2.3254599
B13: Offtake/Tolling Revenue ($M) | C13: $M | D13: =IF(D5=0,0,D8*0.05) -> 0 | E13: =IF(E5=0,0,E8*0.05) -> 0 | F13: =IF(F5=0,0,F8*0.05) -> 0.41690476 | G13: =IF(G5=0,0,G8*0.05) -> 0.83475782 | H13: =IF(H5=0,0,H8*0.05) -> 1.0661224 | I13: =IF(I5=0,0,I8*0.05) -> 1.0685213 | J13: =IF(J5=0,0,J8*0.05) -> 1.0715089 | K13: =IF(K5=0,0,K8*0.05) -> 1.0750814 | ... W13: =IF(W5=0,0,W8*0.05) -> 1.16273
B14: Government Subsidy/Grant Income ($M) | C14: $M | D14: 0 | E14: 0 | F14: 0 | G14: 0 | H14: 0 | I14: 0 | J14: 0 | K14: 0 | L14: 0 | M14: 0 | N14: 0 | O14: 0 | P14: 0 | Q14: 0 | R14: 0 | S14: 0 | T14: 0 | U14: 0 | V14: 0 | W14: 0
B15: Total Gross Revenue ($M) | C15: $M | D15: =SUM(D11:D14) -> 0 | E15: =SUM(E11:E14) -> 0 | F15: =SUM(F11:F14) -> 8.3380952 | G15: =SUM(G11:G14) -> 16.695156 | H15: =SUM(H11:H14) -> 21.322449 | I15: =SUM(I11:I14) -> 21.370427 | J15: =SUM(J11:J14) -> 21.430178 | K15: =SUM(K11:K14) -> 21.501629 | ... W15: =SUM(W11:W14) -> 23.254599
B17: REVENUE ADJUSTMENTS
B18: Withholding Tax on Gross Revenue | C18: $M | D18: =IF(D15=0,0,-D15*Assumptions!C21) -> 0 | E18: =IF(E15=0,0,-E15*Assumptions!C21) -> 0 | F18: =IF(F15=0,0,-F15*Assumptions!C21) -> -0.83380952 | G18: =IF(G15=0,0,-G15*Assumptions!C21) -> -1.6695156 | H18: =IF(H15=0,0,-H15*Assumptions!C21) -> -2.1322449 | I18: =IF(I15=0,0,-I15*Assumptions!C21) -> -2.1370427 | J18: =IF(J15=0,0,-J15*Assumptions!C21) -> -2.1430178 | K18: =IF(K15=0,0,-K15*Assumptions!C21) -> -2.1501629 | L18: =IF(L15=0,0,-L15*Assumptions!C21) -> -2.1584713 | M18: =IF(M15=0,0,-M15*Assumptions!C21) -> -2.1679371 | N18: =IF(N15=0,0,-N15*Assumptions!C21) -> -2.1785553 | O18: =IF(O15=0,0,-O15*Assumptions!C21) -> -2.1903212 | P18: =IF(P15=0,0,-P15*Assumptions!C21) -> -2.2032312 | Q18: =IF(Q15=0,0,-Q15*Assumptions!C21) -> -2.2172821 | R18: =IF(R15=0,0,-R15*Assumptions!C21) -> -2.2324716 | S18: =IF(S15=0,0,-S15*Assumptions!C21) -> -2.2487979 | T18: =IF(T15=0,0,-T15*Assumptions!C21) -> -2.26626 | U18: =IF(U15=0,0,-U15*Assumptions!C21) -> -2.2848574 | V18: =IF(V15=0,0,-V15*Assumptions!C21) -> -2.3045904 | W18: =IF(W15=0,0,-W15*Assumptions!C21) -> -2.3254599
B19: VAT/Sales Tax Impact | C19: $M | D19: =IF(D15=0,0,-D15*Assumptions!C22*0.1) -> 0 | E19: =IF(E15=0,0,-E15*Assumptions!C22*0.1) -> 0 | F19: =IF(F15=0,0,-F15*Assumptions!C22*0.1) -> -0.13340952 | G19: =IF(G15=0,0,-G15*Assumptions!C22*0.1) -> -0.2671225 | H19: =IF(H15=0,0,-H15*Assumptions!C22*0.1) -> -0.34115918 | I19: =IF(I15=0,0,-I15*Assumptions!C22*0.1) -> -0.34192683 | J19: =IF(J15=0,0,-J15*Assumptions!C22*0.1) -> -0.34288285 | K19: =IF(K15=0,0,-K15*Assumptions!C22*0.1) -> -0.34402606 | L19: =IF(L15=0,0,-L15*Assumptions!C22*0.1) -> -0.3453554 | M19: =IF(M15=0,0,-M15*Assumptions!C22*0.1) -> -0.34686994 | N19: =IF(N15=0,0,-N15*Assumptions!C22*0.1) -> -0.34856884 | O19: =IF(O15=0,0,-O15*Assumptions!C22*0.1) -> -0.35045139 | P19: =IF(P15=0,0,-P15*Assumptions!C22*0.1) -> -0.35251699 | Q19: =IF(Q15=0,0,-Q15*Assumptions!C22*0.1) -> -0.35476514 | R19: =IF(R15=0,0,-R15*Assumptions!C22*0.1) -> -0.35719545 | S19: =IF(S15=0,0,-S15*Assumptions!C22*0.1) -> -0.35980766 | T19: =IF(T15=0,0,-T15*Assumptions!C22*0.1) -> -0.36260159 | U19: =IF(U15=0,0,-U15*Assumptions!C22*0.1) -> -0.36557718 | V19: =IF(V15=0,0,-V15*Assumptions!C22*0.1) -> -0.36873446 | W19: =IF(W15=0,0,-W15*Assumptions!C22*0.1) -> -0.37207359
B20: FX Translation Gain/(Loss) | C20: $M | D20: =IF(D15=0,0,-D15*Assumptions!C18/(1+Assumptions!C18)) -> 0 | E20: =IF(E15=0,0,-E15*Assumptions!C18/(1+Assumptions!C18)) -> 0 | F20: =IF(F15=0,0,-F15*Assumptions!C18/(1+Assumptions!C18)) -> -0.39705215 | G20: =IF(G15=0,0,-G15*Assumptions!C18/(1+Assumptions!C18)) -> -0.79500745 | H20: =IF(H15=0,0,-H15*Assumptions!C18/(1+Assumptions!C18)) -> -1.0153547 | I20: =IF(I15=0,0,-I15*Assumptions!C18/(1+Assumptions!C18)) -> -1.0176394 | J20: =IF(J15=0,0,-J15*Assumptions!C18/(1+Assumptions!C18)) -> -1.0204847 | K20: =IF(K15=0,0,-K15*Assumptions!C18/(1+Assumptions!C18)) -> -1.0238871 | L20: =IF(L15=0,0,-L15*Assumptions!C18/(1+Assumptions!C18)) -> -1.0278435 | M20: =IF(M15=0,0,-M15*Assumptions!C18/(1+Assumptions!C18)) -> -1.032351 | N20: =IF(N15=0,0,-N15*Assumptions!C18/(1+Assumptions!C18)) -> -1.0374073 | O20: =IF(O15=0,0,-O15*Assumptions!C18/(1+Assumptions!C18)) -> -1.0430101 | P20: =IF(P15=0,0,-P15*Assumptions!C18/(1+Assumptions!C18)) -> -1.0491577 | Q20: =IF(Q15=0,0,-Q15*Assumptions!C18/(1+Assumptions!C18)) -> -1.0558486 | R20: =IF(R15=0,0,-R15*Assumptions!C18/(1+Assumptions!C18)) -> -1.0630817 | S20: =IF(S15=0,0,-S15*Assumptions!C18/(1+Assumptions!C18)) -> -1.0708561 | T20: =IF(T15=0,0,-T15*Assumptions!C18/(1+Assumptions!C18)) -> -1.0791714 | U20: =IF(U15=0,0,-U15*Assumptions!C18/(1+Assumptions!C18)) -> -1.0880273 | V20: =IF(V15=0,0,-V15*Assumptions!C18/(1+Assumptions!C18)) -> -1.097424 | W20: =IF(W15=0,0,-W15*Assumptions!C18/(1+Assumptions!C18)) -> -1.1073619
B21: Net Revenue ($M, USD) | C21: $M | D21: =D15+D18+D19+D20 -> 0 | E21: =E15+E18+E19+E20 -> 0 | F21: =F15+F18+F19+F20 -> 6.973824 | G21: =G15+G18+G19+G20 -> 13.963511 | H21: =H15+H18+H19+H20 -> 17.83369 | I21: =I15+I18+I19+I20 -> 17.873818 | J21: =J15+J18+J19+J20 -> 17.923793 | K21: =K15+K18+K19+K20 -> 17.983553 | ... W21: =W15+W18+W19+W20 -> 19.449704

Sheet CAPEX Schedule
B1: CAPITAL EXPENDITURE SCHEDULE
B3: CAPEX Component | C3: Total ($M) | D3: Yr 1 | E3: Yr 2 | F3: Yr 3 | G3: Yr 4 | H3: Yr 5 | I3: % of Total
B4: HARD COSTS
B5: Land Acquisition & Site Preparation | C5: =SUM(D5:H5) -> 3 | D5: 1 | E5: 1.5 | F5: 0.5 | G5: 0 | H5: 0
B6: Civil Works & Earthworks | C6: =SUM(D6:H6) -> 6 | D6: 2 | E6: 3 | F6: 1 | G6: 0 | H6: 0
B7: Structural/Building Construction | C7: =SUM(D7:H7) -> 6.5 | D7: 0.5 | E7: 2 | F7: 3 | G7: 1 | H7: 0
B8: Equipment & Machinery (imported) | C8: =SUM(D8:H8) -> 10 | D8: 0 | E8: 3 | F8: 5 | G8: 2 | H8: 0
B9: Equipment & Machinery (local) | C9: =SUM(D9:H9) -> 5 | D9: 0 | E9: 1 | F9: 2 | G9: 1.5 | H9: 0.5
B10: Installation & Commissioning | C10: =SUM(D10:H10) -> 6 | D10: 0 | E10: 0 | F10: 2 | G10: 3 | H10: 1
B11: Utility Connections (power, water) | C11: =SUM(D11:H11) -> 2 | D11: 0.5 | E11: 0.5 | F11: 0.5 | G11: 0.5 | H11: 0
B12: Total Hard Costs | C12: =SUM(C5:C11) -> 38.5 | D12: =SUM(D5:D11) -> 4 | E12: =SUM(E5:E11) -> 11 | F12: =SUM(F5:F11) -> 14 | G12: =SUM(G5:G11) -> 8 | H12: =SUM(H5:H11) -> 1.5
D13: 0 | E13: 0 | F13: 0 | G13: 0 | H13: 0
B14: SOFT COSTS
B15: Engineering & Design (FEED/EPC) | C15: =SUM(D15:H15) -> 2.5 | D15: 0.8 | E15: 1.2 | F15: 0.5 | G15: 0 | H15: 0
B16: Environmental & Social Impact Assessment | C16: =SUM(D16:H16) -> 0.5 | D16: 0.3 | E16: 0.2 | F16: 0 | G16: 0 | H16: 0
B17: Legal & Regulatory (permits, licenses) | C17: =SUM(D17:H17) -> 0.9 | D17: 0.2 | E17: 0.3 | F17: 0.2 | G17: 0.1 | H17: 0.1
B18: Insurance (construction period) | C18: =SUM(D18:H18) -> 0.8 | D18: 0.1 | E18: 0.2 | F18: 0.2 | G18: 0.2 | H18: 0.1
B19: Project Management & Owner's Engineer | C19: =SUM(D19:H19) -> 1.8 | D19: 0.3 | E19: 0.5 | F19: 0.5 | G19: 0.3 | H19: 0.2
B20: Interest During Construction (IDC) | C20: =SUM(D20:H20) -> 1.4 | D20: 0 | E20: 0.3 | F20: 0.5 | G20: 0.4 | H20: 0.2
B21: Total Soft Costs | C21: =SUM(C15:C20) -> 7.9 | D21: =SUM(D15:D20) -> 1.7 | E21: =SUM(E15:E20) -> 2.7 | F21: =SUM(F15:F20) -> 1.9 | G21: =SUM(G15:G20) -> 1 | H21: =SUM(H15:H20) -> 0.6
D22: 0 | E22: 0 | F22: 0 | G22: 0 | H22: 0
B23: CONTINGENCY & RESERVES
B24: Physical Contingency | C24: =(C12+C21)*Assumptions!C42 -> 4.64 | D24: 0 | E24: 0 | F24: 0 | G24: 0 | H24: 0
B25: Price Contingency (inflation) | C25: =(C12+C21)*Assumptions!C39*2 -> 3.712 | D25: 0 | E25: 0 | F25: 0 | G25: 0 | H25: 0
B26: FX Contingency | C26: =(C12+C21)*Assumptions!C18 -> 2.32 | D26: 0 | E26: 0 | F26: 0 | G26: 0 | H26: 0
B27: Total Contingency | C27: =SUM(C24:C26) -> 10.672
D28: 0 | E28: 0 | F28: 0 | G28: 0 | H28: 0
B29: TOTAL PROJECT CAPEX | C29: =C12+C21+C27 -> 57.072 | D29: 0 | E29: 0 | F29: 0 | G29: 0 | H29: 0

Sheet OPEX Schedule
B1: OPERATING EXPENDITURE SCHEDULE
B3: OPEX Component | C3: Unit | D3: 1 | E3: 2 | F3: 3 | G3: 4 | H3: 5 | I3: 6 | J3: 7 | K3: 8 | L3: 9 | M3: 10 | N3: 11 | O3: 12 | P3: 13 | Q3: 14 | R3: 15 | S3: 16 | T3: 17 | U3: 18 | V3: 19 | W3: 20
B4: FIXED OPERATING COSTS
B5: Staff & Labor (local) | C5: $M | D5: =IF(1<=(Assumptions!C31/12),0,'CAPEX Schedule'!C29*0.015*(1+Assumptions!C39)^MAX(0,1-(Assumptions!C31/12))) -> 0 | E5: =IF(2<=(Assumptions!C31/12),0,'CAPEX Schedule'!C29*0.015*(1+Assumptions!C39)^MAX(0,2-(Assumptions!C31/12))) -> 0 | F5: =IF(3<=(Assumptions!C31/12),0,'CAPEX Schedule'!C29*0.015*(1+Assumptions!C39)^MAX(0,3-(Assumptions!C31/12))) -> 0.8903232 | G5: =IF(4<=(Assumptions!C31/12),0,'CAPEX Schedule'!C29*0.015*(1+Assumptions!C39)^MAX(0,4-(Assumptions!C31/12))) -> 0.92593613 | H5: =IF(5<=(Assumptions!C31/12),0,'CAPEX Schedule'!C29*0.015*(1+Assumptions!C39)^MAX(0,5-(Assumptions!C31/12))) -> 0.96297357 | I5: =IF(6<=(Assumptions!C31/12),0,'CAPEX Schedule'!C29*0.015*(1+Assumptions!C39)^MAX(0,6-(Assumptions!C31/12))) -> 1.0014925 | J5: =IF(7<=(Assumptions!C31/12),0,'CAPEX Schedule'!C29*0.015*(1+Assumptions!C39)^MAX(0,7-(Assumptions!C31/12))) -> 1.0415522 | K5: =IF(8<=(Assumptions!C31/12),0,'CAPEX Schedule'!C29*0.015*(1+Assumptions!C39)^MAX(0,8-(Assumptions!C31/12))) -> 1.0832143 | L5: =IF(9<=(Assumptions!C31/12),0,'CAPEX Schedule'!C29*0.015*(1+Assumptions!C39)^MAX(0,9-(Assumptions!C31/12))) -> 1.1265429 | M5: =IF(10<=(Assumptions!C31/12),0,'CAPEX Schedule'!C29*0.015*(1+Assumptions!C39)^MAX(0,10-(Assumptions!C31/12))) -> 1.1716046 | N5: =IF(11<=(Assumptions!C31/12),0,'CAPEX Schedule'!C29*0.015*(1+Assumptions!C39)^MAX(0,11-(Assumptions!C31/12))) -> 1.2184688 | O5: =IF(12<=(Assumptions!C31/12),0,'CAPEX Schedule'!C29*0.015*(1+Assumptions!C39)^MAX(0,12-(Assumptions!C31/12))) -> 1.2672075 | P5: =IF(13<=(Assumptions!C31/12),0,'CAPEX Schedule'!C29*0.015*(1+Assumptions!C39)^MAX(0,13-(Assumptions!C31/12))) -> 1.3178958 | Q5: =IF(14<=(Assumptions!C31/12),0,'CAPEX Schedule'!C29*0.015*(1+Assumptions!C39)^MAX(0,14-(Assumptions!C31/12))) -> 1.3706117 | R5: =IF(15<=(Assumptions!C31/12),0,'CAPEX Schedule'!C29*0.015*(1+Assumptions!C39)^MAX(0,15-(Assumptions!C31/12))) -> 1.4254361 | S5: =IF(16<=(Assumptions!C31/12),0,'CAPEX Schedule'!C29*0.015*(1+Assumptions!C39)^MAX(0,16-(Assumptions!C31/12))) -> 1.4824536 | T5: =IF(17<=(Assumptions!C31/12),0,'CAPEX Schedule'!C29*0.015*(1+Assumptions!C39)^MAX(0,17-(Assumptions!C31/12))) -> 1.5417517 | U5: =IF(18<=(Assumptions!C31/12),0,'CAPEX Schedule'!C29*0.015*(1+Assumptions!C39)^MAX(0,18-(Assumptions!C31/12))) -> 1.6034218 | V5: =IF(19<=(Assumptions!C31/12),0,'CAPEX Schedule'!C29*0.015*(1+Assumptions!C39)^MAX(0,19-(Assumptions!C31/12))) -> 1.6675587 | W5: =IF(20<=(Assumptions!C31/12),0,'CAPEX Schedule'!C29*0.015*(1+Assumptions!C39)^MAX(0,20-(Assumptions!C31/12))) -> 1.734261
B6: Staff & Labor (expatriate) | C6: $M | D6: =IF(1<=(Assumptions!C31/12),0,'CAPEX Schedule'!C29*0.008*(1+Assumptions!C39)^MAX(0,1-(Assumptions!C31/12))) -> 0 | E6: =IF(2<=(Assumptions!C31/12),0,'CAPEX Schedule'!C29*0.008*(1+Assumptions!C39)^MAX(0,2-(Assumptions!C31/12))) -> 0 | F6: =IF(3<=(Assumptions!C31/12),0,'CAPEX Schedule'!C29*0.008*(1+Assumptions!C39)^MAX(0,3-(Assumptions!C31/12))) -> 0.47483904 | G6: =IF(4<=(Assumptions!C31/12),0,'CAPEX Schedule'!C29*0.008*(1+Assumptions!C39)^MAX(0,4-(Assumptions!C31/12))) -> 0.4938326 | H6: =IF(5<=(Assumptions!C31/12),0,'CAPEX Schedule'!C29*0.008*(1+Assumptions!C39)^MAX(0,5-(Assumptions!C31/12))) -> 0.51358591 | I6: =IF(6<=(Assumptions!C31/12),0,'CAPEX Schedule'!C29*0.008*(1+Assumptions!C39)^MAX(0,6-(Assumptions!C31/12))) -> 0.53412934 | J6: =IF(7<=(Assumptions!C31/12),0,'CAPEX Schedule'!C29*0.008*(1+Assumptions!C39)^MAX(0,7-(Assumptions!C31/12))) -> 0.55549452 | K6: =IF(8<=(Assumptions!C31/12),0,'CAPEX Schedule'!C29*0.008*(1+Assumptions!C39)^MAX(0,8-(Assumptions!C31/12))) -> 0.5777143 | L6: =IF(9<=(Assumptions!C31/12),0,'CAPEX Schedule'!C29*0.008*(1+Assumptions!C39)^MAX(0,9-(Assumptions!C31/12))) -> 0.60082287 | M6: =IF(10<=(Assumptions!C31/12),0,'CAPEX Schedule'!C29*0.008*(1+Assumptions!C39)^MAX(0,10-(Assumptions!C31/12))) -> 0.62485578 | N6: =IF(11<=(Assumptions!C31/12),0,'CAPEX Schedule'!C29*0.008*(1+Assumptions!C39)^MAX(0,11-(Assumptions!C31/12))) -> 0.64985001 | O6: =IF(12<=(Assumptions!C31/12),0,'CAPEX Schedule'!C29*0.008*(1+Assumptions!C39)^MAX(0,12-(Assumptions!C31/12))) -> 0.67584401 | P6: =IF(13<=(Assumptions!C31/12),0,'CAPEX Schedule'!C29*0.008*(1+Assumptions!C39)^MAX(0,13-(Assumptions!C31/12))) -> 0.70287778 | Q6: =IF(14<=(Assumptions!C31/12),0,'CAPEX Schedule'!C29*0.008*(1+Assumptions!C39)^MAX(0,14-(Assumptions!C31/12))) -> 0.73099289 | R6: =IF(15<=(Assumptions!C31/12),0,'CAPEX Schedule'!C29*0.008*(1+Assumptions!C39)^MAX(0,15-(Assumptions!C31/12))) -> 0.7602326 | S6: =IF(16<=(Assumptions!C31/12),0,'CAPEX Schedule'!C29*0.008*(1+Assumptions!C39)^MAX(0,16-(Assumptions!C31/12))) -> 0.79064191 | T6: =IF(17<=(Assumptions!C31/12),0,'CAPEX Schedule'!C29*0.008*(1+Assumptions!C39)^MAX(0,17-(Assumptions!C31/12))) -> 0.82226758 | U6: =IF(18<=(Assumptions!C31/12),0,'CAPEX Schedule'!C29*0.008*(1+Assumptions!C39)^MAX(0,18-(Assumptions!C31/12))) -> 0.85515829 | V6: =IF(19<=(Assumptions!C31/12),0,'CAPEX Schedule'!C29*0.008*(1+Assumptions!C39)^MAX(0,19-(Assumptions!C31/12))) -> 0.88936462 | W6: =IF(20<=(Assumptions!C31/12),0,'CAPEX Schedule'!C29*0.008*(1+Assumptions!C39)^MAX(0,20-(Assumptions!C31/12))) -> 0.9249392
B7: Insurance (operational) | C7: $M | D7: =IF(1<=(Assumptions!C31/12),0,'CAPEX Schedule'!C29*0.004*(1+Assumptions!C39)^MAX(0,1-(Assumptions!C31/12))) -> 0 | E7: =IF(2<=(Assumptions!C31/12),0,'CAPEX Schedule'!C29*0.004*(1+Assumptions!C39)^MAX(0,2-(Assumptions!C31/12))) -> 0 | F7: =IF(3<=(Assumptions!C31/12),0,'CAPEX Schedule'!C29*0.004*(1+Assumptions!C39)^MAX(0,3-(Assumptions!C31/12))) -> 0.23741952 | G7: =IF(4<=(Assumptions!C31/12),0,'CAPEX Schedule'!C29*0.004*(1+Assumptions!C39)^MAX(0,4-(Assumptions!C31/12))) -> 0.2469163 | H7: =IF(5<=(Assumptions!C31/12),0,'CAPEX Schedule'!C29*0.004*(1+Assumptions!C39)^MAX(0,5-(Assumptions!C31/12))) -> 0.25679295 | I7: =IF(6<=(Assumptions!C31/12),0,'CAPEX Schedule'!C29*0.004*(1+Assumptions!C39)^MAX(0,6-(Assumptions!C31/12))) -> 0.26706467 | J7: =IF(7<=(Assumptions!C31/12),0,'CAPEX Schedule'!C29*0.004*(1+Assumptions!C39)^MAX(0,7-(Assumptions!C31/12))) -> 0.27774726 | K7: =IF(8<=(Assumptions!C31/12),0,'CAPEX Schedule'!C29*0.004*(1+Assumptions!C39)^MAX(0,8-(Assumptions!C31/12))) -> 0.28885715 | L7: =IF(9<=(Assumptions!C31/12),0,'CAPEX Schedule'!C29*0.004*(1+Assumptions!C39)^MAX(0,9-(Assumptions!C31/12))) -> 0.30041143 | M7: =IF(10<=(Assumptions!C31/12),0,'CAPEX Schedule'!C29*0.004*(1+Assumptions!C39)^MAX(0,10-(Assumptions!C31/12))) -> 0.31242789 | N7: =IF(11<=(Assumptions!C31/12),0,'CAPEX Schedule'!C29*0.004*(1+Assumptions!C39)^MAX(0,11-(Assumptions!C31/12))) -> 0.32492501 | O7: =IF(12<=(Assumptions!C31/12),0,'CAPEX Schedule'!C29*0.004*(1+Assumptions!C39)^MAX(0,12-(Assumptions!C31/12))) -> 0.33792201 | P7: =IF(13<=(Assumptions!C31/12),0,'CAPEX Schedule'!C29*0.004*(1+Assumptions!C39)^MAX(0,13-(Assumptions!C31/12))) -> 0.35143889 | Q7: =IF(14<=(Assumptions!C31/12),0,'CAPEX Schedule'!C29*0.004*(1+Assumptions!C39)^MAX(0,14-(Assumptions!C31/12))) -> 0.36549644 | R7: =IF(15<=(Assumptions!C31/12),0,'CAPEX Schedule'!C29*0.004*(1+Assumptions!C39)^MAX(0,15-(Assumptions!C31/12))) -> 0.3801163 | S7: =IF(16<=(Assumptions!C31/12),0,'CAPEX Schedule'!C29*0.004*(1+Assumptions!C39)^MAX(0,16-(Assumptions!C31/12))) -> 0.39532095 | T7: =IF(17<=(Assumptions!C31/12),0,'CAPEX Schedule'!C29*0.004*(1+Assumptions!C39)^MAX(0,17-(Assumptions!C31/12))) -> 0.41113379 | U7: =IF(18<=(Assumptions!C31/12),0,'CAPEX Schedule'!C29*0.004*(1+Assumptions!C39)^MAX(0,18-(Assumptions!C31/12))) -> 0.42757914 | V7: =IF(19<=(Assumptions!C31/12),0,'CAPEX Schedule'!C29*0.004*(1+Assumptions!C39)^MAX(0,19-(Assumptions!C31/12))) -> 0.44468231 | W7: =IF(20<=(Assumptions!C31/12),0,'CAPEX Schedule'!C29*0.004*(1+Assumptions!C39)^MAX(0,20-(Assumptions!C31/12))) -> 0.4624696
B8: Land Lease / Concession Fee | C8: $M | D8: =IF(1<=(Assumptions!C31/12),0,'CAPEX Schedule'!C29*0.002*(1+Assumptions!C39)^MAX(0,1-(Assumptions!C31/12))) -> 0 | E8: =IF(2<=(Assumptions!C31/12),0,'CAPEX Schedule'!C29*0.002*(1+Assumptions!C39)^MAX(0,2-(Assumptions!C31/12))) -> 0 | F8: =IF(3<=(Assumptions!C31/12),0,'CAPEX Schedule'!C29*0.002*(1+Assumptions!C39)^MAX(0,3-(Assumptions!C31/12))) -> 0.11870976 | G8: =IF(4<=(Assumptions!C31/12),0,'CAPEX Schedule'!C29*0.002*(1+Assumptions!C39)^MAX(0,4-(Assumptions!C31/12))) -> 0.12345815 | H8: =IF(5<=(Assumptions!C31/12),0,'CAPEX Schedule'!C29*0.002*(1+Assumptions!C39)^MAX(0,5-(Assumptions!C31/12))) -> 0.12839648 | I8: =IF(6<=(Assumptions!C31/12),0,'CAPEX Schedule'!C29*0.002*(1+Assumptions!C39)^MAX(0,6-(Assumptions!C31/12))) -> 0.13353234 | J8: =IF(7<=(Assumptions!C31/12),0,'CAPEX Schedule'!C29*0.002*(1+Assumptions!C39)^MAX(0,7-(Assumptions!C31/12))) -> 0.13887363 | K8: =IF(8<=(Assumptions!C31/12),0,'CAPEX Schedule'!C29*0.002*(1+Assumptions!C39)^MAX(0,8-(Assumptions!C31/12))) -> 0.14442857 | L8: =IF(9<=(Assumptions!C31/12),0,'CAPEX Schedule'!C29*0.002*(1+Assumptions!C39)^MAX(0,9-(Assumptions!C31/12))) -> 0.15020572 | M8: =IF(10<=(Assumptions!C31/12),0,'CAPEX Schedule'!C29*0.002*(1+Assumptions!C39)^MAX(0,10-(Assumptions!C31/12))) -> 0.15621395 | N8: =IF(11<=(Assumptions!C31/12),0,'CAPEX Schedule'!C29*0.002*(1+Assumptions!C39)^MAX(0,11-(Assumptions!C31/12))) -> 0.1624625 | O8: =IF(12<=(Assumptions!C31/12),0,'CAPEX Schedule'!C29*0.002*(1+Assumptions!C39)^MAX(0,12-(Assumptions!C31/12))) -> 0.168961 | P8: =IF(13<=(Assumptions!C31/12),0,'CAPEX Schedule'!C29*0.002*(1+Assumptions!C39)^MAX(0,13-(Assumptions!C31/12))) -> 0.17571944 | Q8: =IF(14<=(Assumptions!C31/12),0,'CAPEX Schedule'!C29*0.002*(1+Assumptions!C39)^MAX(0,14-(Assumptions!C31/12))) -> 0.18274822 | R8: =IF(15<=(Assumptions!C31/12),0,'CAPEX Schedule'!C29*0.002*(1+Assumptions!C39)^MAX(0,15-(Assumptions!C31/12))) -> 0.19005815 | S8: =IF(16<=(Assumptions!C31/12),0,'CAPEX Schedule'!C29*0.002*(1+Assumptions!C39)^MAX(0,16-(Assumptions!C31/12))) -> 0.19766048 | T8: =IF(17<=(Assumptions!C31/12),0,'CAPEX Schedule'!C29*0.002*(1+Assumptions!C39)^MAX(0,17-(Assumptions!C31/12))) -> 0.2055669 | U8: =IF(18<=(Assumptions!C31/12),0,'CAPEX Schedule'!C29*0.002*(1+Assumptions!C39)^MAX(0,18-(Assumptions!C31/12))) -> 0.21378957 | V8: =IF(19<=(Assumptions!C31/12),0,'CAPEX Schedule'!C29*0.002*(1+Assumptions!C39)^MAX(0,19-(Assumptions!C31/12))) -> 0.22234115 | W8: =IF(20<=(Assumptions!C31/12),0,'CAPEX Schedule'!C29*0.002*(1+Assumptions!C39)^MAX(0,20-(Assumptions!C31/12))) -> 0.2312348
B9: Security & Community Relations | C9: $M | D9: =IF(1<=(Assumptions!C31/12),0,'CAPEX Schedule'!C29*0.0015*(1+Assumptions!C39)^MAX(0,1-(Assumptions!C31/12))) -> 0 | E9: =IF(2<=(Assumptions!C31/12),0,'CAPEX Schedule'!C29*0.0015*(1+Assumptions!C39)^MAX(0,2-(Assumptions!C31/12))) -> 0 | F9: =IF(3<=(Assumptions!C31/12),0,'CAPEX Schedule'!C29*0.0015*(1+Assumptions!C39)^MAX(0,3-(Assumptions!C31/12))) -> 0.08903232 | G9: =IF(4<=(Assumptions!C31/12),0,'CAPEX Schedule'!C29*0.0015*(1+Assumptions!C39)^MAX(0,4-(Assumptions!C31/12))) -> 0.092593613 | H9: =IF(5<=(Assumptions!C31/12),0,'CAPEX Schedule'!C29*0.0015*(1+Assumptions!C39)^MAX(0,5-(Assumptions!C31/12))) -> 0.096297357 | I9: =IF(6<=(Assumptions!C31/12),0,'CAPEX Schedule'!C29*0.0015*(1+Assumptions!C39)^MAX(0,6-(Assumptions!C31/12))) -> 0.10014925 | J9: =IF(7<=(Assumptions!C31/12),0,'CAPEX Schedule'!C29*0.0015*(1+Assumptions!C39)^MAX(0,7-(Assumptions!C31/12))) -> 0.10415522 | K9: =IF(8<=(Assumptions!C31/12),0,'CAPEX Schedule'!C29*0.0015*(1+Assumptions!C39)^MAX(0,8-(Assumptions!C31/12))) -> 0.10832143 | L9: =IF(9<=(Assumptions!C31/12),0,'CAPEX Schedule'!C29*0.0015*(1+Assumptions!C39)^MAX(0,9-(Assumptions!C31/12))) -> 0.11265429 | M9: =IF(10<=(Assumptions!C31/12),0,'CAPEX Schedule'!C29*0.0015*(1+Assumptions!C39)^MAX(0,10-(Assumptions!C31/12))) -> 0.11716046 | N9: =IF(11<=(Assumptions!C31/12),0,'CAPEX Schedule'!C29*0.0015*(1+Assumptions!C39)^MAX(0,11-(Assumptions!C31/12))) -> 0.12184688 | O9: =IF(12<=(Assumptions!C31/12),0,'CAPEX Schedule'!C29*0.0015*(1+Assumptions!C39)^MAX(0,12-(Assumptions!C31/12))) -> 0.12672075 | P9: =IF(13<=(Assumptions!C31/12),0,'CAPEX Schedule'!C29*0.0015*(1+Assumptions!C39)^MAX(0,13-(Assumptions!C31/12))) -> 0.13178958 | Q9: =IF(14<=(Assumptions!C31/12),0,'CAPEX Schedule'!C29*0.0015*(1+Assumptions!C39)^MAX(0,14-(Assumptions!C31/12))) -> 0.13706117 | R9: =IF(15<=(Assumptions!C31/12),0,'CAPEX Schedule'!C29*0.0015*(1+Assumptions!C39)^MAX(0,15-(Assumptions!C31/12))) -> 0.14254361 | S9: =IF(16<=(Assumptions!C31/12),0,'CAPEX Schedule'!C29*0.0015*(1+Assumptions!C39)^MAX(0,16-(Assumptions!C31/12))) -> 0.14824536 | T9: =IF(17<=(Assumptions!C31/12),0,'CAPEX Schedule'!C29*0.0015*(1+Assumptions!C39)^MAX(0,17-(Assumptions!C31/12))) -> 0.15417517 | U9: =IF(18<=(Assumptions!C31/12),0,'CAPEX Schedule'!C29*0.0015*(1+Assumptions!C39)^MAX(0,18-(Assumptions!C31/12))) -> 0.16034218 | V9: =IF(19<=(Assumptions!C31/12),0,'CAPEX Schedule'!C29*0.0015*(1+Assumptions!C39)^MAX(0,19-(Assumptions!C31/12))) -> 0.16675587 | W9: =IF(20<=(Assumptions!C31/12),0,'CAPEX Schedule'!C29*0.0015*(1+Assumptions!C39)^MAX(0,20-(Assumptions!C31/12))) -> 0.1734261
B10: Total Fixed OPEX | C10: $M | D10: =SUM(D5:D9) -> 0 | E10: =SUM(E5:E9) -> 0 | F10: =SUM(F5:F9) -> 1.8103238 | G10: =SUM(G5:G9) -> 1.8827368 | H10: =SUM(H5:H9) -> 1.9580463 | I10: =SUM(I5:I9) -> 2.0363681 | J10: =SUM(J5:J9) -> 2.1178228 | K10: =SUM(K5:K9) -> 2.2025358 | ... W10: =SUM(W5:W9) -> 3.5263307
B12: VARIABLE OPERATING COSTS
B13: Raw Materials / Consumables | C13: $M | D13: =IF(1<=(Assumptions!C31/12),0,'Revenue Build'!D15*0.06*(1+Assumptions!C39)^MAX(0,1-(Assumptions!C31/12))) -> 0 | E13: =IF(2<=(Assumptions!C31/12),0,'Revenue Build'!E15*0.06*(1+Assumptions!C39)^MAX(0,2-(Assumptions!C31/12))) -> 0 | F13: =IF(3<=(Assumptions!C31/12),0,'Revenue Build'!F15*0.06*(1+Assumptions!C39)^MAX(0,3-(Assumptions!C31/12))) -> 0.52029714 | G13: =IF(4<=(Assumptions!C31/12),0,'Revenue Build'!G15*0.06*(1+Assumptions!C39)^MAX(0,4-(Assumptions!C31/12))) -> 1.0834489 | H13: =IF(5<=(Assumptions!C31/12),0,'Revenue Build'!H15*0.06*(1+Assumptions!C39)^MAX(0,5-(Assumptions!C31/12))) -> 1.4390913 | I13: =IF(6<=(Assumptions!C31/12),0,'Revenue Build'!I15*0.06*(1+Assumptions!C39)^MAX(0,6-(Assumptions!C31/12))) -> 1.5000226 | J13: =IF(7<=(Assumptions!C31/12),0,'Revenue Build'!J15*0.06*(1+Assumptions!C39)^MAX(0,7-(Assumptions!C31/12))) -> 1.5643853 | K13: =IF(8<=(Assumptions!C31/12),0,'Revenue Build'!K15*0.06*(1+Assumptions!C39)^MAX(0,8-(Assumptions!C31/12))) -> 1.6323852 | L13: =IF(9<=(Assumptions!C31/12),0,'Revenue Build'!L15*0.06*(1+Assumptions!C39)^MAX(0,9-(Assumptions!C31/12))) -> 1.7042406 | M13: =IF(10<=(Assumptions!C31/12),0,'Revenue Build'!M15*0.06*(1+Assumptions!C39)^MAX(0,10-(Assumptions!C31/12))) -> 1.780183 | N13: =IF(11<=(Assumptions!C31/12),0,'Revenue Build'!N15*0.06*(1+Assumptions!C39)^MAX(0,11-(Assumptions!C31/12))) -> 1.8604581 | O13: =IF(12<=(Assumptions!C31/12),0,'Revenue Build'!O15*0.06*(1+Assumptions!C39)^MAX(0,12-(Assumptions!C31/12))) -> 1.9453263 | P13: =IF(13<=(Assumptions!C31/12),0,'Revenue Build'!P15*0.06*(1+Assumptions!C39)^MAX(0,13-(Assumptions!C31/12))) -> 2.0350639 | Q13: =IF(14<=(Assumptions!C31/12),0,'Revenue Build'!Q15*0.06*(1+Assumptions!C39)^MAX(0,14-(Assumptions!C31/12))) -> 2.129964 | R13: =IF(15<=(Assumptions!C31/12),0,'Revenue Build'!R15*0.06*(1+Assumptions!C39)^MAX(0,15-(Assumptions!C31/12))) -> 2.2303376 | S13: =IF(16<=(Assumptions!C31/12),0,'Revenue Build'!S15*0.06*(1+Assumptions!C39)^MAX(0,16-(Assumptions!C31/12))) -> 2.3365142 | T13: =IF(17<=(Assumptions!C31/12),0,'Revenue Build'!T15*0.06*(1+Assumptions!C39)^MAX(0,17-(Assumptions!C31/12))) -> 2.4488437 | U13: =IF(18<=(Assumptions!C31/12),0,'Revenue Build'!U15*0.06*(1+Assumptions!C39)^MAX(0,18-(Assumptions!C31/12))) -> 2.567697 | V13: =IF(19<=(Assumptions!C31/12),0,'Revenue Build'!V15*0.06*(1+Assumptions!C39)^MAX(0,19-(Assumptions!C31/12))) -> 2.6934677 | W13: =IF(20<=(Assumptions!C31/12),0,'Revenue Build'!W15*0.06*(1+Assumptions!C39)^MAX(0,20-(Assumptions!C31/12))) -> 2.8265731
B14: Energy / Fuel Costs | C14: $M | D14: =IF(1<=(Assumptions!C31/12),0,'Revenue Build'!D15*0.04*(1+Assumptions!C39)^MAX(0,1-(Assumptions!C31/12))) -> 0 | E14: =IF(2<=(Assumptions!C31/12),0,'Revenue Build'!E15*0.04*(1+Assumptions!C39)^MAX(0,2-(Assumptions!C31/12))) -> 0 | F14: =IF(3<=(Assumptions!C31/12),0,'Revenue Build'!F15*0.04*(1+Assumptions!C39)^MAX(0,3-(Assumptions!C31/12))) -> 0.34686476 | G14: =IF(4<=(Assumptions!C31/12),0,'Revenue Build'!G15*0.04*(1+Assumptions!C39)^MAX(0,4-(Assumptions!C31/12))) -> 0.72229925 | H14: =IF(5<=(Assumptions!C31/12),0,'Revenue Build'!H15*0.04*(1+Assumptions!C39)^MAX(0,5-(Assumptions!C31/12))) -> 0.9593942 | I14: =IF(6<=(Assumptions!C31/12),0,'Revenue Build'!I15*0.04*(1+Assumptions!C39)^MAX(0,6-(Assumptions!C31/12))) -> 1.0000151 | J14: =IF(7<=(Assumptions!C31/12),0,'Revenue Build'!J15*0.04*(1+Assumptions!C39)^MAX(0,7-(Assumptions!C31/12))) -> 1.0429235 | K14: =IF(8<=(Assumptions!C31/12),0,'Revenue Build'!K15*0.04*(1+Assumptions!C39)^MAX(0,8-(Assumptions!C31/12))) -> 1.0882568 | L14: =IF(9<=(Assumptions!C31/12),0,'Revenue Build'!L15*0.04*(1+Assumptions!C39)^MAX(0,9-(Assumptions!C31/12))) -> 1.1361604 | M14: =IF(10<=(Assumptions!C31/12),0,'Revenue Build'!M15*0.04*(1+Assumptions!C39)^MAX(0,10-(Assumptions!C31/12))) -> 1.1867887 | N14: =IF(11<=(Assumptions!C31/12),0,'Revenue Build'!N15*0.04*(1+Assumptions!C39)^MAX(0,11-(Assumptions!C31/12))) -> 1.2403054 | O14: =IF(12<=(Assumptions!C31/12),0,'Revenue Build'!O15*0.04*(1+Assumptions!C39)^MAX(0,12-(Assumptions!C31/12))) -> 1.2968842 | P14: =IF(13<=(Assumptions!C31/12),0,'Revenue Build'!P15*0.04*(1+Assumptions!C39)^MAX(0,13-(Assumptions!C31/12))) -> 1.3567093 | Q14: =IF(14<=(Assumptions!C31/12),0,'Revenue Build'!Q15*0.04*(1+Assumptions!C39)^MAX(0,14-(Assumptions!C31/12))) -> 1.419976 | R14: =IF(15<=(Assumptions!C31/12),0,'Revenue Build'!R15*0.04*(1+Assumptions!C39)^MAX(0,15-(Assumptions!C31/12))) -> 1.4868917 | S14: =IF(16<=(Assumptions!C31/12),0,'Revenue Build'!S15*0.04*(1+Assumptions!C39)^MAX(0,16-(Assumptions!C31/12))) -> 1.5576761 | T14: =IF(17<=(Assumptions!C31/12),0,'Revenue Build'!T15*0.04*(1+Assumptions!C39)^MAX(0,17-(Assumptions!C31/12))) -> 1.6325625 | U14: =IF(18<=(Assumptions!C31/12),0,'Revenue Build'!U15*0.04*(1+Assumptions!C39)^MAX(0,18-(Assumptions!C31/12))) -> 1.711798 | V14: =IF(19<=(Assumptions!C31/12),0,'Revenue Build'!V15*0.04*(1+Assumptions!C39)^MAX(0,19-(Assumptions!C31/12))) -> 1.7956451 | W14: =IF(20<=(Assumptions!C31/12),0,'Revenue Build'!W15*0.04*(1+Assumptions!C39)^MAX(0,20-(Assumptions!C31/12))) -> 1.884382
B15: Maintenance & Repairs | C15: $M | D15: =IF(1<=(Assumptions!C31/12),0,'CAPEX Schedule'!C29*Assumptions!C40*(1+Assumptions!C39)^MAX(0,1-(Assumptions!C31/12))) -> 0 | E15: =IF(2<=(Assumptions!C31/12),0,'CAPEX Schedule'!C29*Assumptions!C40*(1+Assumptions!C39)^MAX(0,2-(Assumptions!C31/12))) -> 0 | F15: =IF(3<=(Assumptions!C31/12),0,'CAPEX Schedule'!C29*Assumptions!C40*(1+Assumptions!C39)^MAX(0,3-(Assumptions!C31/12))) -> 1.1870976 | G15: =IF(4<=(Assumptions!C31/12),0,'CAPEX Schedule'!C29*Assumptions!C40*(1+Assumptions!C39)^MAX(0,4-(Assumptions!C31/12))) -> 1.2345815 | H15: =IF(5<=(Assumptions!C31/12),0,'CAPEX Schedule'!C29*Assumptions!C40*(1+Assumptions!C39)^MAX(0,5-(Assumptions!C31/12))) -> 1.2839648 | I15: =IF(6<=(Assumptions!C31/12),0,'CAPEX Schedule'!C29*Assumptions!C40*(1+Assumptions!C39)^MAX(0,6-(Assumptions!C31/12))) -> 1.3353234 | J15: =IF(7<=(Assumptions!C31/12),0,'CAPEX Schedule'!C29*Assumptions!C40*(1+Assumptions!C39)^MAX(0,7-(Assumptions!C31/12))) -> 1.3887363 | K15: =IF(8<=(Assumptions!C31/12),0,'CAPEX Schedule'!C29*Assumptions!C40*(1+Assumptions!C39)^MAX(0,8-(Assumptions!C31/12))) -> 1.4442857 | L15: =IF(9<=(Assumptions!C31/12),0,'CAPEX Schedule'!C29*Assumptions!C40*(1+Assumptions!C39)^MAX(0,9-(Assumptions!C31/12))) -> 1.5020572 | M15: =IF(10<=(Assumptions!C31/12),0,'CAPEX Schedule'!C29*Assumptions!C40*(1+Assumptions!C39)^MAX(0,10-(Assumptions!C31/12))) -> 1.5621395 | N15: =IF(11<=(Assumptions!C31/12),0,'CAPEX Schedule'!C29*Assumptions!C40*(1+Assumptions!C39)^MAX(0,11-(Assumptions!C31/12))) -> 1.624625 | O15: =IF(12<=(Assumptions!C31/12),0,'CAPEX Schedule'!C29*Assumptions!C40*(1+Assumptions!C39)^MAX(0,12-(Assumptions!C31/12))) -> 1.68961 | P15: =IF(13<=(Assumptions!C31/12),0,'CAPEX Schedule'!C29*Assumptions!C40*(1+Assumptions!C39)^MAX(0,13-(Assumptions!C31/12))) -> 1.7571944 | Q15: =IF(14<=(Assumptions!C31/12),0,'CAPEX Schedule'!C29*Assumptions!C40*(1+Assumptions!C39)^MAX(0,14-(Assumptions!C31/12))) -> 1.8274822 | R15: =IF(15<=(Assumptions!C31/12),0,'CAPEX Schedule'!C29*Assumptions!C40*(1+Assumptions!C39)^MAX(0,15-(Assumptions!C31/12))) -> 1.9005815 | S15: =IF(16<=(Assumptions!C31/12),0,'CAPEX Schedule'!C29*Assumptions!C40*(1+Assumptions!C39)^MAX(0,16-(Assumptions!C31/12))) -> 1.9766048 | T15: =IF(17<=(Assumptions!C31/12),0,'CAPEX Schedule'!C29*Assumptions!C40*(1+Assumptions!C39)^MAX(0,17-(Assumptions!C31/12))) -> 2.055669 | U15: =IF(18<=(Assumptions!C31/12),0,'CAPEX Schedule'!C29*Assumptions!C40*(1+Assumptions!C39)^MAX(0,18-(Assumptions!C31/12))) -> 2.1378957 | V15: =IF(19<=(Assumptions!C31/12),0,'CAPEX Schedule'!C29*Assumptions!C40*(1+Assumptions!C39)^MAX(0,19-(Assumptions!C31/12))) -> 2.2234115 | W15: =IF(20<=(Assumptions!C31/12),0,'CAPEX Schedule'!C29*Assumptions!C40*(1+Assumptions!C39)^MAX(0,20-(Assumptions!C31/12))) -> 2.312348
B16: Transport & Logistics | C16: $M | D16: =IF(1<=(Assumptions!C31/12),0,'Revenue Build'!D15*0.03*(1+Assumptions!C39)^MAX(0,1-(Assumptions!C31/12))) -> 0 | E16: =IF(2<=(Assumptions!C31/12),0,'Revenue Build'!E15*0.03*(1+Assumptions!C39)^MAX(0,2-(Assumptions!C31/12))) -> 0 | F16: =IF(3<=(Assumptions!C31/12),0,'Revenue Build'!F15*0.03*(1+Assumptions!C39)^MAX(0,3-(Assumptions!C31/12))) -> 0.26014857 | G16: =IF(4<=(Assumptions!C31/12),0,'Revenue Build'!G15*0.03*(1+Assumptions!C39)^MAX(0,4-(Assumptions!C31/12))) -> 0.54172444 | H16: =IF(5<=(Assumptions!C31/12),0,'Revenue Build'!H15*0.03*(1+Assumptions!C39)^MAX(0,5-(Assumptions!C31/12))) -> 0.71954565 | I16: =IF(6<=(Assumptions!C31/12),0,'Revenue Build'!I15*0.03*(1+Assumptions!C39)^MAX(0,6-(Assumptions!C31/12))) -> 0.7500113 | J16: =IF(7<=(Assumptions!C31/12),0,'Revenue Build'!J15*0.03*(1+Assumptions!C39)^MAX(0,7-(Assumptions!C31/12))) -> 0.78219265 | K16: =IF(8<=(Assumptions!C31/12),0,'Revenue Build'!K15*0.03*(1+Assumptions!C39)^MAX(0,8-(Assumptions!C31/12))) -> 0.81619259 | L16: =IF(9<=(Assumptions!C31/12),0,'Revenue Build'!L15*0.03*(1+Assumptions!C39)^MAX(0,9-(Assumptions!C31/12))) -> 0.85212028 | M16: =IF(10<=(Assumptions!C31/12),0,'Revenue Build'!M15*0.03*(1+Assumptions!C39)^MAX(0,10-(Assumptions!C31/12))) -> 0.89009149 | N16: =IF(11<=(Assumptions!C31/12),0,'Revenue Build'!N15*0.03*(1+Assumptions!C39)^MAX(0,11-(Assumptions!C31/12))) -> 0.93022903 | O16: =IF(12<=(Assumptions!C31/12),0,'Revenue Build'!O15*0.03*(1+Assumptions!C39)^MAX(0,12-(Assumptions!C31/12))) -> 0.97266313 | P16: =IF(13<=(Assumptions!C31/12),0,'Revenue Build'!P15*0.03*(1+Assumptions!C39)^MAX(0,13-(Assumptions!C31/12))) -> 1.0175319 | Q16: =IF(14<=(Assumptions!C31/12),0,'Revenue Build'!Q15*0.03*(1+Assumptions!C39)^MAX(0,14-(Assumptions!C31/12))) -> 1.064982 | R16: =IF(15<=(Assumptions!C31/12),0,'Revenue Build'!R15*0.03*(1+Assumptions!C39)^MAX(0,15-(Assumptions!C31/12))) -> 1.1151688 | S16: =IF(16<=(Assumptions!C31/12),0,'Revenue Build'!S15*0.03*(1+Assumptions!C39)^MAX(0,16-(Assumptions!C31/12))) -> 1.1682571 | T16: =IF(17<=(Assumptions!C31/12),0,'Revenue Build'!T15*0.03*(1+Assumptions!C39)^MAX(0,17-(Assumptions!C31/12))) -> 1.2244218 | U16: =IF(18<=(Assumptions!C31/12),0,'Revenue Build'!U15*0.03*(1+Assumptions!C39)^MAX(0,18-(Assumptions!C31/12))) -> 1.2838485 | V16: =IF(19<=(Assumptions!C31/12),0,'Revenue Build'!V15*0.03*(1+Assumptions!C39)^MAX(0,19-(Assumptions!C31/12))) -> 1.3467338 | W16: =IF(20<=(Assumptions!C31/12),0,'Revenue Build'!W15*0.03*(1+Assumptions!C39)^MAX(0,20-(Assumptions!C31/12))) -> 1.4132865
B17: Water & Environmental | C17: $M | D17: =IF(1<=(Assumptions!C31/12),0,'Revenue Build'!D15*0.01*(1+Assumptions!C39)^MAX(0,1-(Assumptions!C31/12))) -> 0 | E17: =IF(2<=(Assumptions!C31/12),0,'Revenue Build'!E15*0.01*(1+Assumptions!C39)^MAX(0,2-(Assumptions!C31/12))) -> 0 | F17: =IF(3<=(Assumptions!C31/12),0,'Revenue Build'!F15*0.01*(1+Assumptions!C39)^MAX(0,3-(Assumptions!C31/12))) -> 0.08671619 | G17: =IF(4<=(Assumptions!C31/12),0,'Revenue Build'!G15*0.01*(1+Assumptions!C39)^MAX(0,4-(Assumptions!C31/12))) -> 0.18057481 | H17: =IF(5<=(Assumptions!C31/12),0,'Revenue Build'!H15*0.01*(1+Assumptions!C39)^MAX(0,5-(Assumptions!C31/12))) -> 0.23984855 | I17: =IF(6<=(Assumptions!C31/12),0,'Revenue Build'!I15*0.01*(1+Assumptions!C39)^MAX(0,6-(Assumptions!C31/12))) -> 0.25000377 | J17: =IF(7<=(Assumptions!C31/12),0,'Revenue Build'!J15*0.01*(1+Assumptions!C39)^MAX(0,7-(Assumptions!C31/12))) -> 0.26073088 | K17: =IF(8<=(Assumptions!C31/12),0,'Revenue Build'!K15*0.01*(1+Assumptions!C39)^MAX(0,8-(Assumptions!C31/12))) -> 0.2720642 | L17: =IF(9<=(Assumptions!C31/12),0,'Revenue Build'!L15*0.01*(1+Assumptions!C39)^MAX(0,9-(Assumptions!C31/12))) -> 0.28404009 | M17: =IF(10<=(Assumptions!C31/12),0,'Revenue Build'!M15*0.01*(1+Assumptions!C39)^MAX(0,10-(Assumptions!C31/12))) -> 0.29669716 | N17: =IF(11<=(Assumptions!C31/12),0,'Revenue Build'!N15*0.01*(1+Assumptions!C39)^MAX(0,11-(Assumptions!C31/12))) -> 0.31007634 | O17: =IF(12<=(Assumptions!C31/12),0,'Revenue Build'!O15*0.01*(1+Assumptions!C39)^MAX(0,12-(Assumptions!C31/12))) -> 0.32422104 | P17: =IF(13<=(Assumptions!C31/12),0,'Revenue Build'!P15*0.01*(1+Assumptions!C39)^MAX(0,13-(Assumptions!C31/12))) -> 0.33917732 | Q17: =IF(14<=(Assumptions!C31/12),0,'Revenue Build'!Q15*0.01*(1+Assumptions!C39)^MAX(0,14-(Assumptions!C31/12))) -> 0.35499401 | R17: =IF(15<=(Assumptions!C31/12),0,'Revenue Build'!R15*0.01*(1+Assumptions!C39)^MAX(0,15-(Assumptions!C31/12))) -> 0.37172293 | S17: =IF(16<=(Assumptions!C31/12),0,'Revenue Build'!S15*0.01*(1+Assumptions!C39)^MAX(0,16-(Assumptions!C31/12))) -> 0.38941904 | T17: =IF(17<=(Assumptions!C31/12),0,'Revenue Build'!T15*0.01*(1+Assumptions!C39)^MAX(0,17-(Assumptions!C31/12))) -> 0.40814062 | U17: =IF(18<=(Assumptions!C31/12),0,'Revenue Build'!U15*0.01*(1+Assumptions!C39)^MAX(0,18-(Assumptions!C31/12))) -> 0.4279495 | V17: =IF(19<=(Assumptions!C31/12),0,'Revenue Build'!V15*0.01*(1+Assumptions!C39)^MAX(0,19-(Assumptions!C31/12))) -> 0.44891128 | W17: =IF(20<=(Assumptions!C31/12),0,'Revenue Build'!W15*0.01*(1+Assumptions!C39)^MAX(0,20-(Assumptions!C31/12))) -> 0.47109551
B18: Total Variable OPEX | C18: $M | D18: =SUM(D13:D17) -> 0 | E18: =SUM(E13:E17) -> 0 | F18: =SUM(F13:F17) -> 2.4011243 | G18: =SUM(G13:G17) -> 3.7626289 | H18: =SUM(H13:H17) -> 4.6418444 | I18: =SUM(I13:I17) -> 4.8353761 | J18: =SUM(J13:J17) -> 5.0389686 | K18: =SUM(K13:K17) -> 5.2531845 | ... W18: =SUM(W13:W17) -> 8.9076851
B20: OTHER OPERATING COSTS
B21: Management Fee (GP) | C21: $M | D21: =IF(1<=(Assumptions!C31/12),0,'CAPEX Schedule'!C29*0.02) -> 0 | E21: =IF(2<=(Assumptions!C31/12),0,'CAPEX Schedule'!C29*0.02) -> 0 | F21: =IF(3<=(Assumptions!C31/12),0,'CAPEX Schedule'!C29*0.02) -> 1.14144 | G21: =IF(4<=(Assumptions!C31/12),0,'CAPEX Schedule'!C29*0.02) -> 1.14144 | H21: =IF(5<=(Assumptions!C31/12),0,'CAPEX Schedule'!C29*0.02) -> 1.14144 | I21: =IF(6<=(Assumptions!C31/12),0,'CAPEX Schedule'!C29*0.02) -> 1.14144 | J21: =IF(7<=(Assumptions!C31/12),0,'CAPEX Schedule'!C29*0.02) -> 1.14144 | K21: =IF(8<=(Assumptions!C31/12),0,'CAPEX Schedule'!C29*0.02) -> 1.14144 | L21: =IF(9<=(Assumptions!C31/12),0,'CAPEX Schedule'!C29*0.02) -> 1.14144 | M21: =IF(10<=(Assumptions!C31/12),0,'CAPEX Schedule'!C29*0.02) -> 1.14144 | N21: =IF(11<=(Assumptions!C31/12),0,'CAPEX Schedule'!C29*0.02) -> 1.14144 | O21: =IF(12<=(Assumptions!C31/12),0,'CAPEX Schedule'!C29*0.02) -> 1.14144 | P21: =IF(13<=(Assumptions!C31/12),0,'CAPEX Schedule'!C29*0.02) -> 1.14144 | Q21: =IF(14<=(Assumptions!C31/12),0,'CAPEX Schedule'!C29*0.02) -> 1.14144 | R21: =IF(15<=(Assumptions!C31/12),0,'CAPEX Schedule'!C29*0.02) -> 1.14144 | S21: =IF(16<=(Assumptions!C31/12),0,'CAPEX Schedule'!C29*0.02) -> 1.14144 | T21: =IF(17<=(Assumptions!C31/12),0,'CAPEX Schedule'!C29*0.02) -> 1.14144 | U21: =IF(18<=(Assumptions!C31/12),0,'CAPEX Schedule'!C29*0.02) -> 1.14144 | V21: =IF(19<=(Assumptions!C31/12),0,'CAPEX Schedule'!C29*0.02) -> 1.14144 | W21: =IF(20<=(Assumptions!C31/12),0,'CAPEX Schedule'!C29*0.02) -> 1.14144
B22: Political Risk Insurance | C22: $M | D22: ='CAPEX Schedule'!C29*Assumptions!C19 -> 0.85608 | E22: ='CAPEX Schedule'!C29*Assumptions!C19 -> 0.85608 | F22: ='CAPEX Schedule'!C29*Assumptions!C19 -> 0.85608 | G22: ='CAPEX Schedule'!C29*Assumptions!C19 -> 0.85608 | H22: ='CAPEX Schedule'!C29*Assumptions!C19 -> 0.85608 | I22: ='CAPEX Schedule'!C29*Assumptions!C19 -> 0.85608 | J22: ='CAPEX Schedule'!C29*Assumptions!C19 -> 0.85608 | K22: ='CAPEX Schedule'!C29*Assumptions!C19 -> 0.85608 | L22: ='CAPEX Schedule'!C29*Assumptions!C19 -> 0.85608 | M22: ='CAPEX Schedule'!C29*Assumptions!C19 -> 0.85608 | N22: ='CAPEX Schedule'!C29*Assumptions!C19 -> 0.85608 | O22: ='CAPEX Schedule'!C29*Assumptions!C19 -> 0.85608 | P22: ='CAPEX Schedule'!C29*Assumptions!C19 -> 0.85608 | Q22: ='CAPEX Schedule'!C29*Assumptions!C19 -> 0.85608 | R22: ='CAPEX Schedule'!C29*Assumptions!C19 -> 0.85608 | S22: ='CAPEX Schedule'!C29*Assumptions!C19 -> 0.85608 | T22: ='CAPEX Schedule'!C29*Assumptions!C19 -> 0.85608 | U22: ='CAPEX Schedule'!C29*Assumptions!C19 -> 0.85608 | V22: ='CAPEX Schedule'!C29*Assumptions!C19 -> 0.85608 | W22: ='CAPEX Schedule'!C29*Assumptions!C19 -> 0.85608
B23: FX Hedging Costs | C23: $M | D23: =IF(1<=(Assumptions!C31/12),0,'Revenue Build'!D15*0.005) -> 0 | E23: =IF(2<=(Assumptions!C31/12),0,'Revenue Build'!E15*0.005) -> 0 | F23: =IF(3<=(Assumptions!C31/12),0,'Revenue Build'!F15*0.005) -> 0.041690476 | G23: =IF(4<=(Assumptions!C31/12),0,'Revenue Build'!G15*0.005) -> 0.083475782 | H23: =IF(5<=(Assumptions!C31/12),0,'Revenue Build'!H15*0.005) -> 0.10661224 | I23: =IF(6<=(Assumptions!C31/12),0,'Revenue Build'!I15*0.005) -> 0.10685213 | J23: =IF(7<=(Assumptions!C31/12),0,'Revenue Build'!J15*0.005) -> 0.10715089 | K23: =IF(8<=(Assumptions!C31/12),0,'Revenue Build'!K15*0.005) -> 0.10750814 | L23: =IF(9<=(Assumptions!C31/12),0,'Revenue Build'!L15*0.005) -> 0.10792356 | M23: =IF(10<=(Assumptions!C31/12),0,'Revenue Build'!M15*0.005) -> 0.10839686 | N23: =IF(11<=(Assumptions!C31/12),0,'Revenue Build'!N15*0.005) -> 0.10892776 | O23: =IF(12<=(Assumptions!C31/12),0,'Revenue Build'!O15*0.005) -> 0.10951606 | P23: =IF(13<=(Assumptions!C31/12),0,'Revenue Build'!P15*0.005) -> 0.11016156 | Q23: =IF(14<=(Assumptions!C31/12),0,'Revenue Build'!Q15*0.005) -> 0.11086411 | R23: =IF(15<=(Assumptions!C31/12),0,'Revenue Build'!R15*0.005) -> 0.11162358 | S23: =IF(16<=(Assumptions!C31/12),0,'Revenue Build'!S15*0.005) -> 0.11243989 | T23: =IF(17<=(Assumptions!C31/12),0,'Revenue Build'!T15*0.005) -> 0.113313 | U23: =IF(18<=(Assumptions!C31/12),0,'Revenue Build'!U15*0.005) -> 0.11424287 | V23: =IF(19<=(Assumptions!C31/12),0,'Revenue Build'!V15*0.005) -> 0.11522952 | W23: =IF(20<=(Assumptions!C31/12),0,'Revenue Build'!W15*0.005) -> 0.116273
B24: Maintenance CAPEX | C24: $M | D24: =IF(1<=(Assumptions!C31/12),0,'CAPEX Schedule'!C29*Assumptions!C40) -> 0 | E24: =IF(2<=(Assumptions!C31/12),0,'CAPEX Schedule'!C29*Assumptions!C40) -> 0 | F24: =IF(3<=(Assumptions!C31/12),0,'CAPEX Schedule'!C29*Assumptions!C40) -> 1.14144 | G24: =IF(4<=(Assumptions!C31/12),0,'CAPEX Schedule'!C29*Assumptions!C40) -> 1.14144 | H24: =IF(5<=(Assumptions!C31/12),0,'CAPEX Schedule'!C29*Assumptions!C40) -> 1.14144 | I24: =IF(6<=(Assumptions!C31/12),0,'CAPEX Schedule'!C29*Assumptions!C40) -> 1.14144 | J24: =IF(7<=(Assumptions!C31/12),0,'CAPEX Schedule'!C29*Assumptions!C40) -> 1.14144 | K24: =IF(8<=(Assumptions!C31/12),0,'CAPEX Schedule'!C29*Assumptions!C40) -> 1.14144 | L24: =IF(9<=(Assumptions!C31/12),0,'CAPEX Schedule'!C29*Assumptions!C40) -> 1.14144 | M24: =IF(10<=(Assumptions!C31/12),0,'CAPEX Schedule'!C29*Assumptions!C40) -> 1.14144 | N24: =IF(11<=(Assumptions!C31/12),0,'CAPEX Schedule'!C29*Assumptions!C40) -> 1.14144 | O24: =IF(12<=(Assumptions!C31/12),0,'CAPEX Schedule'!C29*Assumptions!C40) -> 1.14144 | P24: =IF(13<=(Assumptions!C31/12),0,'CAPEX Schedule'!C29*Assumptions!C40) -> 1.14144 | Q24: =IF(14<=(Assumptions!C31/12),0,'CAPEX Schedule'!C29*Assumptions!C40) -> 1.14144 | R24: =IF(15<=(Assumptions!C31/12),0,'CAPEX Schedule'!C29*Assumptions!C40) -> 1.14144 | S24: =IF(16<=(Assumptions!C31/12),0,'CAPEX Schedule'!C29*Assumptions!C40) -> 1.14144 | T24: =IF(17<=(Assumptions!C31/12),0,'CAPEX Schedule'!C29*Assumptions!C40) -> 1.14144 | U24: =IF(18<=(Assumptions!C31/12),0,'CAPEX Schedule'!C29*Assumptions!C40) -> 1.14144 | V24: =IF(19<=(Assumptions!C31/12),0,'CAPEX Schedule'!C29*Assumptions!C40) -> 1.14144 | W24: =IF(20<=(Assumptions!C31/12),0,'CAPEX Schedule'!C29*Assumptions!C40) -> 1.14144
B25: Working Capital Change | C25: $M | D25: =IF(1<=Assumptions!C31/12,0,'Revenue Build'!D15*Assumptions!C41/365) -> 0 | E25: =IF(2<=Assumptions!C31/12,0,'Revenue Build'!E15*Assumptions!C41/365-'Revenue Build'!D15*Assumptions!C41/365) -> 0 | F25: =IF(3<=Assumptions!C31/12,0,'Revenue Build'!F15*Assumptions!C41/365-'Revenue Build'!E15*Assumptions!C41/365) -> 1.3706458 | G25: =IF(4<=Assumptions!C31/12,0,'Revenue Build'!G15*Assumptions!C41/365-'Revenue Build'!F15*Assumptions!C41/365) -> 1.3737635 | H25: =IF(5<=Assumptions!C31/12,0,'Revenue Build'!H15*Assumptions!C41/365-'Revenue Build'!G15*Assumptions!C41/365) -> 0.76065077 | I25: =IF(6<=Assumptions!C31/12,0,'Revenue Build'!I15*Assumptions!C41/365-'Revenue Build'!H15*Assumptions!C41/365) -> 0.0078868168 | J25: =IF(7<=Assumptions!C31/12,0,'Revenue Build'!J15*Assumptions!C41/365-'Revenue Build'!I15*Assumptions!C41/365) -> 0.009822107 | K25: =IF(8<=Assumptions!C31/12,0,'Revenue Build'!K15*Assumptions!C41/365-'Revenue Build'!J15*Assumptions!C41/365) -> 0.011745316 | L25: =IF(9<=Assumptions!C31/12,0,'Revenue Build'!L15*Assumptions!C41/365-'Revenue Build'!K15*Assumptions!C41/365) -> 0.013657652 | M25: =IF(10<=Assumptions!C31/12,0,'Revenue Build'!M15*Assumptions!C41/365-'Revenue Build'!L15*Assumptions!C41/365) -> 0.015560309 | N25: =IF(11<=Assumptions!C31/12,0,'Revenue Build'!N15*Assumptions!C41/365-'Revenue Build'!M15*Assumptions!C41/365) -> 0.017454462 | O25: =IF(12<=Assumptions!C31/12,0,'Revenue Build'!O15*Assumptions!C41/365-'Revenue Build'!N15*Assumptions!C41/365) -> 0.019341271 | P25: =IF(13<=Assumptions!C31/12,0,'Revenue Build'!P15*Assumptions!C41/365-'Revenue Build'!O15*Assumptions!C41/365) -> 0.021221881 | Q25: =IF(14<=Assumptions!C31/12,0,'Revenue Build'!Q15*Assumptions!C41/365-'Revenue Build'!P15*Assumptions!C41/365) -> 0.023097424 | R25: =IF(15<=Assumptions!C31/12,0,'Revenue Build'!R15*Assumptions!C41/365-'Revenue Build'!Q15*Assumptions!C41/365) -> 0.024969017 | S25: =IF(16<=Assumptions!C31/12,0,'Revenue Build'!S15*Assumptions!C41/365-'Revenue Build'!R15*Assumptions!C41/365) -> 0.026837767 | T25: =IF(17<=Assumptions!C31/12,0,'Revenue Build'!T15*Assumptions!C41/365-'Revenue Build'!S15*Assumptions!C41/365) -> 0.028704767 | U25: =IF(18<=Assumptions!C31/12,0,'Revenue Build'!U15*Assumptions!C41/365-'Revenue Build'!T15*Assumptions!C41/365) -> 0.0305711 | V25: =IF(19<=Assumptions!C31/12,0,'Revenue Build'!V15*Assumptions!C41/365-'Revenue Build'!U15*Assumptions!C41/365) -> 0.032437838 | W25: =IF(20<=Assumptions!C31/12,0,'Revenue Build'!W15*Assumptions!C41/365-'Revenue Build'!V15*Assumptions!C41/365) -> 0.034306045
B26: Total Other Costs | C26: $M | D26: =SUM(D21:D25) -> 0.85608 | E26: =SUM(E21:E25) -> 0.85608 | F26: =SUM(F21:F25) -> 4.5512963 | G26: =SUM(G21:G25) -> 4.5961993 | H26: =SUM(H21:H25) -> 4.006223 | I26: =SUM(I21:I25) -> 3.253699 | J26: =SUM(J21:J25) -> 3.255933 | K26: =SUM(K21:K25) -> 3.2582135 | ... W26: =SUM(W21:W25) -> 3.289539
B28: TOTAL OPEX | D28: =D10+D18+D26 -> 0.85608 | E28: =E10+E18+E26 -> 0.85608 | F28: =F10+F18+F26 -> 8.7627444 | G28: =G10+G18+G26 -> 10.241565 | H28: =H10+H18+H26 -> 10.606114 | I28: =I10+I18+I26 -> 10.125443 | J28: =J10+J18+J26 -> 10.412724 | K28: =K10+K18+K26 -> 10.713934 | ... W28: =W10+W18+W26 -> 15.723555

Sheet Financing Structure
B1: MULTI-TRANCHE FINANCING & DEBT SERVICE
B3: Financing Component | C3: Unit | D3: 1 | E3: 2 | F3: 3 | G3: 4 | H3: 5 | I3: 6 | J3: 7 | K3: 8 | L3: 9 | M3: 10 | N3: 11 | O3: 12 | P3: 13 | Q3: 14 | R3: 15 | S3: 16 | T3: 17 | U3: 18 | V3: 19 | W3: 20
B4: SOURCES OF FUNDS
B5: Senior Debt Drawdown | C5: $M
B6: Mezzanine Debt Drawdown | C6: $M
B7: DFI/Concessional Drawdown | C7: $M
B8: Equity Injection | C8: $M
B9: Total Sources | C9: $M
B11: SENIOR DEBT SERVICE
B12: Opening Balance | C12: $M | D12: 0 | E12: =D16 -> 15.6948 | F12: =E16 -> 31.3896 | G12: =F16 -> 31.3896 | H12: =G16 -> 31.3896 | I12: =H16 -> 27.901867 | J12: =I16 -> 24.414133 | K12: =J16 -> 20.9264 | L12: =K16 -> 17.438667 | ... W12: =V16 -> 0
B13: Drawdowns | C13: $M | D13: =IF(1<=(Assumptions!C31/12),'CAPEX Schedule'!C29*Assumptions!C46/(Assumptions!C31/12),0) -> 15.6948 | E13: =IF(2<=(Assumptions!C31/12),'CAPEX Schedule'!C29*Assumptions!C46/(Assumptions!C31/12),0) -> 15.6948 | F13: =IF(3<=(Assumptions!C31/12),'CAPEX Schedule'!C29*Assumptions!C46/(Assumptions!C31/12),0) -> 0 | G13: =IF(4<=(Assumptions!C31/12),'CAPEX Schedule'!C29*Assumptions!C46/(Assumptions!C31/12),0) -> 0 | H13: =IF(5<=(Assumptions!C31/12),'CAPEX Schedule'!C29*Assumptions!C46/(Assumptions!C31/12),0) -> 0 | I13: =IF(6<=(Assumptions!C31/12),'CAPEX Schedule'!C29*Assumptions!C46/(Assumptions!C31/12),0) -> 0 | J13: =IF(7<=(Assumptions!C31/12),'CAPEX Schedule'!C29*Assumptions!C46/(Assumptions!C31/12),0) -> 0 | K13: =IF(8<=(Assumptions!C31/12),'CAPEX Schedule'!C29*Assumptions!C46/(Assumptions!C31/12),0) -> 0 | L13: =IF(9<=(Assumptions!C31/12),'CAPEX Schedule'!C29*Assumptions!C46/(Assumptions!C31/12),0) -> 0 | M13: =IF(10<=(Assumptions!C31/12),'CAPEX Schedule'!C29*Assumptions!C46/(Assumptions!C31/12),0) -> 0 | N13: =IF(11<=(Assumptions!C31/12),'CAPEX Schedule'!C29*Assumptions!C46/(Assumptions!C31/12),0) -> 0 | O13: =IF(12<=(Assumptions!C31/12),'CAPEX Schedule'!C29*Assumptions!C46/(Assumptions!C31/12),0) -> 0 | P13: =IF(13<=(Assumptions!C31/12),'CAPEX Schedule'!C29*Assumptions!C46/(Assumptions!C31/12),0) -> 0 | Q13: =IF(14<=(Assumptions!C31/12),'CAPEX Schedule'!C29*Assumptions!C46/(Assumptions!C31/12),0) -> 0 | R13: =IF(15<=(Assumptions!C31/12),'CAPEX Schedule'!C29*Assumptions!C46/(Assumptions!C31/12),0) -> 0 | S13: =IF(16<=(Assumptions!C31/12),'CAPEX Schedule'!C29*Assumptions!C46/(Assumptions!C31/12),0) -> 0 | T13: =IF(17<=(Assumptions!C31/12),'CAPEX Schedule'!C29*Assumptions!C46/(Assumptions!C31/12),0) -> 0 | U13: =IF(18<=(Assumptions!C31/12),'CAPEX Schedule'!C29*Assumptions!C46/(Assumptions!C31/12),0) -> 0 | V13: =IF(19<=(Assumptions!C31/12),'CAPEX Schedule'!C29*Assumptions!C46/(Assumptions!C31/12),0) -> 0 | W13: =IF(20<=(Assumptions!C31/12),'CAPEX Schedule'!C29*Assumptions!C46/(Assumptions!C31/12),0) -> 0
